Workbook

Sheet Report
J2: No of Days | L2: 42
J3: Shoppers Engaged per Promoter per Day | L3: =10*L2 -> 420
J4: Shoppers Converted per Promoter per Day | L4: =L3*70% -> 294
J6: Target Combos Per day | L6: 25
J7: DB Selling Price per Case | L7: 1888
J8: Agency Selling Price per Case | L8: 2000
J9: Margin | L9: 112
A10: Date: 11-08-2026
F12: Agency Team | I12: Reconciliation
B13: 11857 | C13: Area | D13: Supervisor | E13: No of DB's | F13: No of Supervisors | G13: No of BA's | H13: Daily Expected Target | I13: Hollandia Evap Milk 120g(Picked by Combos) | J13: Hollandia Evap Milk 120g(Sold by Combos) | K13: TOTAL | L13: DB Amount to be Reconciled | M13: Agency Amount to be Reconciled | N13: DB Picked from | O13: Market/Neighbourhood Visited
B14: 0.23608338 | C14: Enugu | F14: 1 | G14: 10 | H14: =G$16*L$8*L$6 -> 500000
B15: 0.12878964 | C15: Abakaliki | F15: 1 | G15: 10 | H15: =G$16*L$8*L$6 -> 500000
B16: 0.2527044 | C16: Onitsha | F16: 1 | G16: 10 | H16: =G$16*L$8*L$6 -> 500000 | AE16: Hollandia Evap Milk 120g
B17: 0.10980083 | C17: Asaba | F17: 1 | G17: 10 | H17: =G$16*L$8*L$6 -> 500000
B18: 0.27262176 | C18: Owerri | F18: 1 | G18: 10 | H18: =G$16*L$8*L$6 -> 500000
B19: #N/A | C19: EAST 1 | E19: =SUM(E14:E18) -> 0 | F19: =SUM(F14:F18) -> 5 | G19: =SUM(G14:G18) -> 50 | H19: =SUM(H14:H18) -> 2500000 | J19: =SUM(J14:J18) -> 0 | K19: =SUM(K14:K18) -> 0
B20: 0.23548802 | C20: Aba | F20: 1 | G20: 10 | H20: =G$16*L$8*L$6 -> 500000
B21: 0.20875543 | C21: Phc 1 | F21: 1 | G21: 10 | H21: =G$16*L$8*L$6 -> 500000
B22: 0.19516803 | C22: Phc 2 | F22: 1 | G22: 10 | H22: =G$16*L$8*L$6 -> 500000
B23: 0.065645602 | C23: Bayelsa | F23: 1 | G23: 10 | H23: =G$16*L$8*L$6 -> 500000
B24: 0.10729217 | C24: Uyo | F24: 1 | G24: 10 | H24: =G$16*L$8*L$6 -> 500000
B25: 0.18765075 | C25: Calabar | D25: Akpan Enoidem | F25: 1 | G25: 10 | H25: =G$16*L$8*L$6 -> 500000 | I25: 41 | J25: 41 | K25: =J$25*2000 -> 82000 | L25: =J$25*1888 -> 77408 | M25: =J$25*112 -> 4592 | N25: POLYTEX | O25: ETTA AGBOR & EDIM OTOP
B26: #N/A | C26: EAST 2 | E26: =SUM(E20:E25) -> 0 | F26: =SUM(F20:F25) -> 6 | G26: =SUM(G20:G25) -> 60 | H26: =SUM(H20:H25) -> 3000000 | I26: 41 | J26: =SUM(J20:J25) -> 41 | K26: =SUM(K20:K25) -> 82000 | L26: =SUM(L25) -> 77408 | M26: =SUM(M25) -> 4592
C27: Ado-Ekiti | D27: Akingbolu Isiaka Opeyemi | G27: 10 | H27: =G$16*L$8*L$6 -> 500000 | I27: 60 | J27: 60 | K27: =J27*2000 -> 120000 | L27: =J27*1888 -> 113280 | M27: =J27*112 -> 6720 | N27: GADAMS ROYAL PULS | O27: POST OFFICE, ATIKANKAN
G28: 10 | H28: =G$16*L$8*L$6 -> 500000
G29: 10 | H29: =G$16*L$8*L$6 -> 500000
B30: #N/A | C30: WEST 1 | E30: =SUM(E21:E26) -> 0 | F30: =SUM(F21:F26) -> 11 | G30: =SUM(G27:G29) -> 30 | H30: =SUM(H27:H29) -> 1500000 | I30: =SUM(I27:I29) -> 60 | J30: =SUM(J27:J29) -> 60 | K30: =SUM(K27:K29) -> 120000 | L30: =SUM(L27:L29) -> 113280 | M30: =SUM(M27:M29) -> 6720
C31: TOTAL 3DIM | E31: =E19+E26 -> 0 | F31: =F19+F26 -> 11 | G31: =G19+G26+G30 -> 140 | H31: =H19+H26+H30 -> 7000000 | I31: =SUM(I26+I19+I30) -> 101 | J31: =SUM(J26+J19+J30) -> 101 | K31: =SUM(K26+K19+K30) -> 202000 | L31: =SUM(L26+L19+L30) -> 190688 | M31: =SUM(M26+M19+M30) -> 11312
A33: Date: 12-08-2026
F35: Agency Team | I35: Reconciliation
B36: 11857 | C36: Area | D36: Supervisor | E36: No of DB's | F36: No of Supervisors | G36: No of BA's | H36: Daily Expected Target | I36: Hollandia Evap Milk 120g(Picked by Combos) | J36: Hollandia Evap Milk 120g(Sold by Combos) | K36: TOTAL | L36: DB Amount to be Reconciled | M36: Agency Amount to be Reconciled | N36: DB Picked from | O36: Market/Neighbourhood Visited
B37: 0.23608338 | C37: Enugu | F37: 1 | G37: 10 | H37: =G$16*L$8*L$6 -> 500000
B38: 0.12878964 | C38: Abakaliki | F38: 1 | G38: 10 | H38: =G$16*L$8*L$6 -> 500000
B39: 0.2527044 | C39: Onitsha | F39: 1 | G39: 10 | H39: =G$16*L$8*L$6 -> 500000
B40: 0.10980083 | C40: Asaba | F40: 1 | G40: 10 | H40: =G$16*L$8*L$6 -> 500000
B41: 0.27262176 | C41: Owerri | F41: 1 | G41: 10 | H41: =G$16*L$8*L$6 -> 500000
B42: #N/A | C42: EAST 1 | E42: =SUM(E37:E41) -> 0 | F42: =SUM(F37:F41) -> 5 | G42: =SUM(G37:G41) -> 50 | H42: =SUM(H37:H41) -> 2500000 | J42: =SUM(J37:J41) -> 0 | K42: =SUM(K37:K41) -> 0
B43: 0.23548802 | C43: Aba | F43: 1 | G43: 10 | H43: =G$16*L$8*L$6 -> 500000
B44: 0.20875543 | C44: Phc 1 | F44: 1 | G44: 10 | H44: =G$16*L$8*L$6 -> 500000
B45: 0.19516803 | C45: Phc 2 | F45: 1 | G45: 10 | H45: =G$16*L$8*L$6 -> 500000
...

Sheet Detail1
A1: Details for Sum of Expected No of Promoters - Region: West 1
A3: Weeks | B3: Region | C3: Area/Location | D3: Agency Supervisor | E3: Commenced? | F3: Expected No of Promoters | G3: Actual Manning | H3: %Ach. | I3: Man Days | J3: Target Consumer days | K3: Actual Consumer Days | L3: No of Drop Points Created | M3: Target Hollandia Evap Milk 120g | N3: Actual Hollandia Evap Milk 120g | O3: Cash Expected | P3: Cash Paid | Q3: TARGET PER REGION | R3: ACTUAL PER REGION | S3: Column1 | T3: Target Volume | U3: Total Volume
B4: West 1 | C4: Ilorin | D4: SEGUN OLORUNTOBA | E4: YES | F4: 0 | G4: 0 | H4: 0 | I4: 0 | J4: 0 | K4: 0 | L4: 0 | M4: 0 | N4: 0 | O4: 0 | P4: 0 | Q4: 0 | R4: 0 | T4: 0 | U4: 0
B5: West 1 | C5: Oshogbo | D5: KOLADE TEMITOPE | E5: YES | F5: 0 | G5: 0 | H5: 0 | I5: 0 | J5: 0 | K5: 0 | L5: 0 | M5: 0 | N5: 0 | O5: 0 | P5: 0 | Q5: 0 | R5: 0 | T5: 0 | U5: 0
B6: West 1 | C6: Ibadan 2 | D6: ALABI OPEYEMI | E6: YES | F6: 0 | G6: 0 | H6: 0 | I6: 0 | J6: 0 | K6: 0 | L6: 0 | M6: 0 | N6: 0 | O6: 0 | P6: 0 | Q6: 0 | R6: 0 | T6: 0 | U6: 0
B7: West 1 | C7: Ibadan 1 | D7: OWOLABI TOLULOPE | E7: YES | F7: 0 | G7: 0 | H7: 0 | I7: 0 | J7: 0 | K7: 0 | L7: 0 | M7: 0 | N7: 0 | O7: 0 | P7: 0 | Q7: 0 | R7: 0 | T7: 0 | U7: 0

Sheet Detail2
A1: Details for Sum of Actual Manning - Region: West 1
A3: Weeks | B3: Region | C3: Area/Location | D3: Agency Supervisor | E3: Commenced? | F3: Expected No of Promoters | G3: Actual Manning | H3: %Ach. | I3: Man Days | J3: Target Consumer days | K3: Actual Consumer Days | L3: No of Drop Points Created | M3: Target Hollandia Evap Milk 120g | N3: Actual Hollandia Evap Milk 120g | O3: Cash Expected | P3: Cash Paid | Q3: TARGET PER REGION | R3: ACTUAL PER REGION | S3: Column1 | T3: Target Volume | U3: Total Volume
B4: West 1 | C4: Ilorin | D4: SEGUN OLORUNTOBA | E4: YES | F4: 0 | G4: 0 | H4: 0 | I4: 0 | J4: 0 | K4: 0 | L4: 0 | M4: 0 | N4: 0 | O4: 0 | P4: 0 | Q4: 0 | R4: 0 | T4: 0 | U4: 0
B5: West 1 | C5: Oshogbo | D5: KOLADE TEMITOPE | E5: YES | F5: 0 | G5: 0 | H5: 0 | I5: 0 | J5: 0 | K5: 0 | L5: 0 | M5: 0 | N5: 0 | O5: 0 | P5: 0 | Q5: 0 | R5: 0 | T5: 0 | U5: 0
B6: West 1 | C6: Ibadan 2 | D6: ALABI OPEYEMI | E6: YES | F6: 0 | G6: 0 | H6: 0 | I6: 0 | J6: 0 | K6: 0 | L6: 0 | M6: 0 | N6: 0 | O6: 0 | P6: 0 | Q6: 0 | R6: 0 | T6: 0 | U6: 0
B7: West 1 | C7: Ibadan 1 | D7: OWOLABI TOLULOPE | E7: YES | F7: 0 | G7: 0 | H7: 0 | I7: 0 | J7: 0 | K7: 0 | L7: 0 | M7: 0 | N7: 0 | O7: 0 | P7: 0 | Q7: 0 | R7: 0 | T7: 0 | U7: 0

Sheet Sheet6
A3: Row Labels | B3: Sum of cases
A4: Ado-Ekiti | B4: 197
A5: Akure | B5: 70
A6: Asaba | B6: 72
A7: Benin | B7: 97
A8: Calabar | B8: 77
A9: Enugu | B9: 62
A10: uyo | B10: 80
A11: Grand Total | B11: 655

Sheet Sheet4
B1: Calabar | C1: Akpan Enoidem | D1: yes | E1: 12 | F1: 12 | H1: 1 | I1: 720 | K1: 41 | L1: 41 | N1: 82000 | O1: 82000
B2: Ado-Ekiti | C2: Akigbolu Isiaka | D2: yes | E2: 12 | F2: 12 | H2: 1 | I2: 720 | K2: 60 | L2: 60 | N2: 120000 | O2: 120000
B3: uyo | C3: Victor Umeh | D3: yes | E3: 12 | F3: 12 | H3: 1 | I3: 720 | K3: 48 | L3: 48 | N3: 96000 | O3: 96000
B4: Calabar | C4: Akpan Enoidem | D4: YES | E4: 12 | F4: 12 | H4: 1 | I4: 720 | K4: 36 | L4: 36 | N4: 72000 | O4: 72000
B5: Ado-Ekiti | C5: Akigbolu Isiaka | D5: yes | E5: 12 | F5: 12 | H5: 1 | I5: 720 | K5: 72 | L5: 72 | N5: 144000 | O5: 144000
B6: Enugu | C6: Mudia | D6: yes | E6: 12 | F6: 12 | H6: 1 | I6: 720 | K6: 62 | L6: 62 | N6: 124630 | O6: 117651
B7: Asaba | C7: IFEANYI CHIADIKABIA | D7: yes | E7: 12 | F7: 12 | H7: 1 | I7: 720 | K7: 72 | L7: 72 | N7: 144000 | O7: 135935
B8: uyo | C8: Victor Umeh | E8: 12 | F8: 12 | H8: 1 | I8: 720 | K8: 32 | L8: 32 | N8: 64000 | O8: 60416
B9: Ado-Ekiti | C9: AKINGBOLU ISIAKA OPEYEMI | E9: 12 | F9: 12 | H9: 1 | I9: 720 | K9: 65 | L9: 65 | N9: 130000 | O9: 122720
B10: Benin | C10: JAMES OLUWASEGUN | E10: 12 | F10: 12 | H10: 1 | I10: 720 | K10: 97 | L10: 97 | N10: 194000 | O10: 183136
B11: Akure | C11: JEROME | E11: 12 | F11: 12 | H11: 1 | I11: 720 | K11: 70 | L11: 70 | N11: 140000 | O11: 132160

Sheet ATD >
L1: Daily sales target per BA | M1: 21
I3: Promoters Update | L3: Man Days | M3: No of Work Days | N3: Hollandia Evap Milk 120g | Q3: Cash Reconciliation | T3: Sales Performance
C4: S/N | D4: Region | E4: Area/Location | F4: Agency Supervisor | G4: Commenced? | H4: Date of Commencement | I4: Expected No of Promoters | J4: Actual Manning | K4: %Ach. | Q4: Cash Reconciliation | T4: PER REGION
N5: Target | O5: Actual | P5: %Ach. | Q5: Expected | R5: Paid | S5: Variance | T5: TARGET | U5: ACTUAL | V5: %ACD
C6: 1 | D6: East 1 | E6: Enugu | K6: =IFERROR(J6/I6,0) -> 0 | L6: =SUMIF(Total!G:G,'ATD >'!E6,Total!K:K) -> 0 | M6: =SUMIF(Total!G:G,'ATD >'!E6,Total!M:M) -> 0 | N6: =I6*M6*$M$1 -> 0 | O6: =SUMIF(Total!G:G,'ATD >'!E6,Total!P:P) -> 0 | P6: =IFERROR(O6/N6,0) -> 0 | Q6: =O6*2000 -> 0 | R6: =SUMIF(Total!G:G,'ATD >'!E6,Total!T:T) -> 0 | S6: =Q6-R6 -> 0 | T6: =I6*M6*2000*21 -> 0 | U6: =R6 -> 0 | V6: =IFERROR(U6/T6,0) -> 0
C7: 2 | D7: East 1 | E7: Abakaliki | K7: =IFERROR(J7/I7,0) -> 0 | L7: =SUMIF(Total!G:G,'ATD >'!E7,Total!K:K) -> 0 | M7: =SUMIF(Total!G:G,'ATD >'!E7,Total!M:M) -> 0 | N7: =I7*M7*$M$1 -> 0 | O7: =SUMIF(Total!G:G,'ATD >'!E7,Total!P:P) -> 0 | P7: =IFERROR(O7/N7,0) -> 0 | Q7: =O7*2000 -> 0 | R7: =SUMIF(Total!G:G,'ATD >'!E7,Total!T:T) -> 0 | S7: =Q7-R7 -> 0 | T7: =I7*M7*2000*21 -> 0 | U7: =R7 -> 0 | V7: =IFERROR(U7/T7,0) -> 0
C8: 3 | D8: East 1 | E8: Onitsha | K8: =IFERROR(J8/I8,0) -> 0 | L8: =SUMIF(Total!G:G,'ATD >'!E8,Total!K:K) -> 120 | M8: =SUMIF(Total!G:G,'ATD >'!E8,Total!M:M) -> 10 | N8: =I8*M8*$M$1 -> 0 | O8: =SUMIF(Total!G:G,'ATD >'!E8,Total!P:P) -> 1477 | P8: =IFERROR(O8/N8,0) -> 0 | Q8: =O8*2000 -> 2954000 | R8: =SUMIF(Total!G:G,'ATD >'!E8,Total!T:T) -> 2792792 | S8: =Q8-R8 -> 161208 | T8: =I8*M8*2000*21 -> 0 | U8: =R8 -> 2792792 | V8: =IFERROR(U8/T8,0) -> 0
C9: 4 | D9: East 1 | E9: Asaba | K9: =IFERROR(J9/I9,0) -> 0 | L9: =SUMIF(Total!G:G,'ATD >'!E9,Total!K:K) -> 108 | M9: =SUMIF(Total!G:G,'ATD >'!E9,Total!M:M) -> 9 | N9: =I9*M9*$M$1 -> 0 | O9: =SUMIF(Total!G:G,'ATD >'!E9,Total!P:P) -> 674 | P9: =IFERROR(O9/N9,0) -> 0 | Q9: =O9*2000 -> 1348000 | R9: =SUMIF(Total!G:G,'ATD >'!E9,Total!T:T) -> 1272512 | S9: =Q9-R9 -> 75488 | T9: =I9*M9*2000*21 -> 0 | U9: =R9 -> 1272512 | V9: =IFERROR(U9/T9,0) -> 0
C10: 5 | D10: East 1 | E10: Owerri | K10: =IFERROR(J10/I10,0) -> 0 | L10: =SUMIF(Total!G:G,'ATD >'!E10,Total!K:K) -> 192 | M10: =SUMIF(Total!G:G,'ATD >'!E10,Total!M:M) -> 16 | N10: =I10*M10*$M$1 -> 0 | O10: =SUMIF(Total!G:G,'ATD >'!E10,Total!P:P) -> 3399 | P10: =IFERROR(O10/N10,0) -> 0 | Q10: =O10*2000 -> 6798000 | R10: =SUMIF(Total!G:G,'ATD >'!E10,Total!T:T) -> 6476896 | S10: =Q10-R10 -> 321104 | T10: =I10*M10*2000*21 -> 0 | U10: =R10 -> 6476896 | V10: =IFERROR(U10/T10,0) -> 0
C11: 6 | D11: East 2 | E11: Aba | K11: =IFERROR(J11/I11,0) -> 0 | L11: =SUMIF(Total!G:G,'ATD >'!E11,Total!K:K) -> 12 | M11: =SUMIF(Total!G:G,'ATD >'!E11,Total!M:M) -> 1 | N11: =I11*M11*$M$1 -> 0 | O11: =SUMIF(Total!G:G,'ATD >'!E11,Total!P:P) -> 53 | P11: =IFERROR(O11/N11,0) -> 0 | Q11: =O11*2000 -> 106000 | R11: =SUMIF(Total!G:G,'ATD >'!E11,Total!T:T) -> 100064 | S11: =Q11-R11 -> 5936 | T11: =I11*M11*2000*21 -> 0 | U11: =R11 -> 100064 | V11: =IFERROR(U11/T11,0) -> 0
C12: 7 | D12: East 2 | E12: PHC 1 | K12: =IFERROR(J12/I12,0) -> 0 | L12: =SUMIF(Total!G:G,'ATD >'!E12,Total!K:K) -> 168 | M12: =SUMIF(Total!G:G,'ATD >'!E12,Total!M:M) -> 14 | N12: =I12*M12*$M$1 -> 0 | O12: =SUMIF(Total!G:G,'ATD >'!E12,Total!P:P) -> 2337 | P12: =IFERROR(O12/N12,0) -> 0 | Q12: =O12*2000 -> 4674000 | R12: =SUMIF(Total!G:G,'ATD >'!E12,Total!T:T) -> 4440480 | S12: =Q12-R12 -> 233520 | T12: =I12*M12*2000*21 -> 0 | U12: =R12 -> 4440480 | V12: =IFERROR(U12/T12,0) -> 0
C13: 8 | D13: East 2 | E13: PHC 2 | K13: =IFERROR(J13/I13,0) -> 0 | L13: =SUMIF(Total!G:G,'ATD >'!E13,Total!K:K) -> 0 | M13: =SUMIF(Total!G:G,'ATD >'!E13,Total!M:M) -> 0 | N13: =I13*M13*$M$1 -> 0 | O13: =SUMIF(Total!G:G,'ATD >'!E13,Total!P:P) -> 0 | P13: =IFERROR(O13/N13,0) -> 0 | Q13: =O13*2000 -> 0 | R13: =SUMIF(Total!G:G,'ATD >'!E13,Total!T:T) -> 0 | S13: =Q13-R13 -> 0 | T13: =I13*M13*2000*21 -> 0 | U13: =R13 -> 0 | V13: =IFERROR(U13/T13,0) -> 0
C14: 9 | D14: East 2 | E14: Bayelsa | K14: =IFERROR(J14/I14,0) -> 0 | L14: =SUMIF(Total!G:G,'ATD >'!E14,Total!K:K) -> 120 | M14: =SUMIF(Total!G:G,'ATD >'!E14,Total!M:M) -> 10 | N14: =I14*M14*$M$1 -> 0 | O14: =SUMIF(Total!G:G,'ATD >'!E14,Total!P:P) -> 2240 | P14: =IFERROR(O14/N14,0) -> 0 | Q14: =O14*2000 -> 4480000 | R14: =SUMIF(Total!G:G,'ATD >'!E14,Total!T:T) -> 4265211 | S14: =Q14-R14 -> 214789 | T14: =I14*M14*2000*21 -> 0 | U14: =R14 -> 4265211 | V14: =IFERROR(U14/T14,0) -> 0
C15: 10 | D15: East 2 | E15: Uyo | F15: Victor Umeh | G15: yes | H15: 46246 | I15: 12 | J15: 12 | K15: =IFERROR(J15/I15,0) -> 1 | L15: =SUMIF(Total!G:G,'ATD >'!E15,Total!K:K) -> 168 | M15: =SUMIF(Total!G:G,'ATD >'!E15,Total!M:M) -> 14 | N15: =I15*M15*$M$1 -> 3528 | O15: =SUMIF(Total!G:G,'ATD >'!E15,Total!P:P) -> 1756 | P15: =IFERROR(O15/N15,0) -> 0.49773243 | Q15: =O15*2000 -> 3512000 | R15: =SUMIF(Total!G:G,'ATD >'!E15,Total!T:T) -> 3315328 | S15: =Q15-R15 -> 196672 | T15: =I15*M15*2000*21 -> 7056000 | U15: =R15 -> 3315328 | V15: =IFERROR(U15/T15,0) -> 0.46985941
C16: 11 | D16: East 2 | E16: Calabar | F16: ENOIDEM AKPAN | G16: Yes | H16: 46245 | I16: 12 | J16: 12 | K16: =IFERROR(J16/I16,0) -> 1 | L16: =SUMIF(Total!G:G,'ATD >'!E16,Total!K:K) -> 144 | M16: =SUMIF(Total!G:G,'ATD >'!E16,Total!M:M) -> 12 | N16: =I16*M16*$M$1 -> 3024 | O16: =SUMIF(Total!G:G,'ATD >'!E16,Total!P:P) -> 1326 | P16: =IFERROR(O16/N16,0) -> 0.43849206 | Q16: =O16*2000 -> 2652000 | R16: =SUMIF(Total!G:G,'ATD >'!E16,Total!T:T) -> 2513980 | S16: =Q16-R16 -> 138020 | T16: =I16*M16*2000*21 -> 6048000 | U16: =R16 -> 2513980 | V16: =IFERROR(U16/T16,0) -> 0.4156713
C17: 12 | D17: West 1 | E17: Ibadan 1 | K17: =IFERROR(J17/I17,0) -> 0 | L17: =SUMIF(Total!G:G,'ATD >'!E17,Total!K:K) -> 0 | M17: =SUMIF(Total!G:G,'ATD >'!E17,Total!M:M) -> 0 | N17: =I17*M17*$M$1 -> 0 | O17: =SUMIF(Total!G:G,'ATD >'!E17,Total!P:P) -> 0 | P17: =IFERROR(O17/N17,0) -> 0 | Q17: =O17*2000 -> 0 | R17: =SUMIF(Total!G:G,'ATD >'!E17,Total!T:T) -> 0 | S17: =Q17-R17 -> 0 | T17: =I17*M17*2000*21 -> 0 | U17: =R17 -> 0 | V17: =IFERROR(U17/T17,0) -> 0
C18: 13 | D18: West 1 | E18: Ibadan 2 | K18: =IFERROR(J18/I18,0) -> 0 | L18: =SUMIF(Total!G:G,'ATD >'!E18,Total!K:K) -> 0 | M18: =SUMIF(Total!G:G,'ATD >'!E18,Total!M:M) -> 0 | N18: =I18*M18*$M$1 -> 0 | O18: =SUMIF(Total!G:G,'ATD >'!E18,Total!P:P) -> 0 | P18: =IFERROR(O18/N18,0) -> 0 | Q18: =O18*2000 -> 0 | R18: =SUMIF(Total!G:G,'ATD >'!E18,Total!T:T) -> 0 | S18: =Q18-R18 -> 0 | T18: =I18*M18*2000*21 -> 0 | U18: =R18 -> 0 | V18: =IFERROR(U18/T18,0) -> 0
C19: 14 | D19: West 1 | E19: Oshogbo | K19: =IFERROR(J19/I19,0) -> 0 | L19: =SUMIF(Total!G:G,'ATD >'!E19,Total!K:K) -> 0 | M19: =SUMIF(Total!G:G,'ATD >'!E19,Total!M:M) -> 0 | N19: =I19*M19*$M$1 -> 0 | O19: =SUMIF(Total!G:G,'ATD >'!E19,Total!P:P) -> 0 | P19: =IFERROR(O19/N19,0) -> 0 | Q19: =O19*2000 -> 0 | R19: =SUMIF(Total!G:G,'ATD >'!E19,Total!T:T) -> 0 | S19: =Q19-R19 -> 0 | T19: =I19*M19*2000*21 -> 0 | U19: =R19 -> 0 | V19: =IFERROR(U19/T19,0) -> 0
C20: 15 | D20: West 1 | E20: Ilorin | K20: =IFERROR(J20/I20,0) -> 0 | L20: =SUMIF(Total!G:G,'ATD >'!E20,Total!K:K) -> 0 | M20: =SUMIF(Total!G:G,'ATD >'!E20,Total!M:M) -> 0 | N20: =I20*M20*$M$1 -> 0 | O20: =SUMIF(Total!G:G,'ATD >'!E20,Total!P:P) -> 0 | P20: =IFERROR(O20/N20,0) -> 0 | Q20: =O20*2000 -> 0 | R20: =SUMIF(Total!G:G,'ATD >'!E20,Total!T:T) -> 0 | S20: =Q20-R20 -> 0 | T20: =I20*M20*2000*21 -> 0 | U20: =R20 -> 0 | V20: =IFERROR(U20/T20,0) -> 0
C21: 16 | D21: West 2 | E21: Benin 1 | K21: =IFERROR(J21/I21,0) -> 0 | L21: =SUMIF(Total!G:G,'ATD >'!E21,Total!K:K) -> 0 | M21: =SUMIF(Total!G:G,'ATD >'!E21,Total!M:M) -> 0 | N21: =I21*M21*$M$1 -> 0 | O21: =SUMIF(Total!G:G,'ATD >'!E21,Total!P:P) -> 0 | P21: =IFERROR(O21/N21,0) -> 0 | Q21: =O21*2000 -> 0 | R21: =SUMIF(Total!G:G,'ATD >'!E21,Total!T:T) -> 0 | S21: =Q21-R21 -> 0 | T21: =I21*M21*2000*21 -> 0 | U21: =R21 -> 0 | V21: =IFERROR(U21/T21,0) -> 0
C22: 17 | D22: West 2 | E22: Benin 2 | K22: =IFERROR(J22/I22,0) -> 0 | L22: =SUMIF(Total!G:G,'ATD >'!E22,Total!K:K) -> 0 | M22: =SUMIF(Total!G:G,'ATD >'!E22,Total!M:M) -> 0 | N22: =I22*M22*$M$1 -> 0 | O22: =SUMIF(Total!G:G,'ATD >'!E22,Total!P:P) -> 0 | P22: =IFERROR(O22/N22,0) -> 0 | Q22: =O22*2000 -> 0 | R22: =SUMIF(Total!G:G,'ATD >'!E22,Total!T:T) -> 0 | S22: =Q22-R22 -> 0 | T22: =I22*M22*2000*21 -> 0 | U22: =R22 -> 0 | V22: =IFERROR(U22/T22,0) -> 0
C23: 18 | D23: West 2 | E23: Akure 1 | K23: =IFERROR(J23/I23,0) -> 0 | L23: =SUMIF(Total!G:G,'ATD >'!E23,Total!K:K) -> 0 | M23: =SUMIF(Total!G:G,'ATD >'!E23,Total!M:M) -> 0 | N23: =I23*M23*$M$1 -> 0 | O23: =SUMIF(Total!G:G,'ATD >'!E23,Total!P:P) -> 0 | P23: =IFERROR(O23/N23,0) -> 0 | Q23: =O23*2000 -> 0 | R23: =SUMIF(Total!G:G,'ATD >'!E23,Total!T:T) -> 0 | S23: =Q23-R23 -> 0 | T23: =I23*M23*2000*21 -> 0 | U23: =R23 -> 0 | V23: =IFERROR(U23/T23,0) -> 0
C24: 19 | D24: West 2 | E24: Ado-Ekiti | F24: Akingbolu Isiaka | G24: Yes | H24: 46245 | I24: 12 | J24: 12 | K24: =IFERROR(J24/I24,0) -> 1 | L24: =SUMIF(Total!G:G,'ATD >'!E24,Total!K:K) -> 144 | M24: =SUMIF(Total!G:G,'ATD >'!E24,Total!M:M) -> 12 | N24: =I24*M24*$M$1 -> 3024 | O24: =SUMIF(Total!G:G,'ATD >'!E24,Total!P:P) -> 1686 | P24: =IFERROR(O24/N24,0) -> 0.55753968 | Q24: =O24*2000 -> 3372000 | R24: =SUMIF(Total!G:G,'ATD >'!E24,Total!T:T) -> 3220296 | S24: =Q24-R24 -> 151704 | T24: =I24*M24*2000*21 -> 6048000 | U24: =R24 -> 3220296 | V24: =IFERROR(U24/T24,0) -> 0.53245635
C25: 20 | D25: West 2 | E25: Warri | K25: =IFERROR(J25/I25,0) -> 0 | L25: =SUMIF(Total!G:G,'ATD >'!E25,Total!K:K) -> 156 | M25: =SUMIF(Total!G:G,'ATD >'!E25,Total!M:M) -> 13 | N25: =I25*M25*$M$1 -> 0 | O25: =SUMIF(Total!G:G,'ATD >'!E25,Total!P:P) -> 2550 | P25: =IFERROR(O25/N25,0) -> 0 | Q25: =O25*2000 -> 5100000 | R25: =SUMIF(Total!G:G,'ATD >'!E25,Total!T:T) -> 4852412 | S25: =Q25-R25 -> 247588 | T25: =I25*M25*2000*21 -> 0 | U25: =R25 -> 4852412 | V25: =IFERROR(U25/T25,0) -> 0
C26: TOTAL | I26: =SUM(I6:I25) -> 36 | J26: =SUM(J6:J25) -> 36 | K26: =J26/I26 -> 1 | L26: =SUM(L6:L25) -> 1332 | M26: =SUM(M6:M25) -> 111 | N26: =SUM(N6:N25) -> 9576 | O26: =SUM(O6:O25) -> 17498 | P26: =O26/N26 -> 1.8272765 | Q26: =SUM(Q6:Q25) -> 34996000 | R26: =SUM(R6:R25) -> 33249971 | S26: =SUM(S6:S25) -> 1746029 | T26: =SUM(T6:T25) -> 19152000 | U26: =SUM(U6:U25) -> 33249971 | V26: =IFERROR(U26/T26,0) -> 1.7361096
I33: Promoters Update | Q33: Cash Reconciliation | T33: Sales Performance
G34: Region | I34: Expected No of Promoters | J34: Actual Manning | K34: %Ach. | L34: Man Days | M34: No of Work Days | N34: Hollandia Evap Milk 120g | Q34: Cash Reconciliation | T34: PER REGION
N35: Target | O35: Actual | P35: %Ach. | Q35: Expected | R35: Paid | S35: Variance | T35: TARGET | U35: ACTUAL | V35: %ACD
G36: East 1 | I36: =SUMIF($D$6:$D$25,$G36,I$6:I$25) -> 0 | J36: =SUMIF($D$6:$D$25,$G36,J$6:J$25) -> 0 | K36: =IFERROR(J36/I36,"") | L36: =SUMIF($D$6:$D$25,$G36,L$6:L$25) -> 420 | M36: =SUMIF($D$6:$D$25,$G36,M$6:M$25) -> 35 | N36: =SUMIF($D$6:$D$25,$G36,N$6:N$25) -> 0 | O36: =SUMIF($D$6:$D$25,$G36,O$6:O$25) -> 5550 | P36: =IFERROR(O36/N36,"") | Q36: =SUMIF($D$6:$D$25,$G36,Q$6:Q$25) -> 11100000 | R36: =SUMIF($D$6:$D$25,$G36,R$6:R$25) -> 10542200 | S36: =R36-Q36 -> -557800 | T36: =SUMIF($D$6:$D$25,$G36,T$6:T$25) -> 0 | U36: =SUMIF($D$6:$D$25,$G36,U$6:U$25) -> 10542200 | V36: =IFERROR(U36/T36,"")
G37: East 2 | I37: =SUMIF($D$6:$D$25,$G37,I$6:I$25) -> 24 | J37: =SUMIF($D$6:$D$25,$G37,J$6:J$25) -> 24 | K37: =IFERROR(J37/I37,"") -> 1 | L37: =SUMIF($D$6:$D$25,$G37,L$6:L$25) -> 612 | M37: =SUMIF($D$6:$D$25,$G37,M$6:M$25) -> 51 | N37: =SUMIF($D$6:$D$25,$G37,N$6:N$25) -> 6552 | O37: =SUMIF($D$6:$D$25,$G37,O$6:O$25) -> 7712 | P37: =IFERROR(O37/N37,"") -> 1.1770452 | Q37: =SUMIF($D$6:$D$25,$G37,Q$6:Q$25) -> 15424000 | R37: =SUMIF($D$6:$D$25,$G37,R$6:R$25) -> 14635063 | S37: =R37-Q37 -> -788937 | T37: =SUMIF($D$6:$D$25,$G37,T$6:T$25) -> 13104000 | U37: =SUMIF($D$6:$D$25,$G37,U$6:U$25) -> 14635063 | V37: =IFERROR(U37/T37,"") -> 1.1168394
G38: West 1 | I38: =SUMIF($D$6:$D$25,$G38,I$6:I$25) -> 0 | J38: =SUMIF($D$6:$D$25,$G38,J$6:J$25) -> 0 | K38: =IFERROR(J38/I38,"") | L38: =SUMIF($D$6:$D$25,$G38,L$6:L$25) -> 0 | M38: =SUMIF($D$6:$D$25,$G38,M$6:M$25) -> 0 | N38: =SUMIF($D$6:$D$25,$G38,N$6:N$25) -> 0 | O38: =SUMIF($D$6:$D$25,$G38,O$6:O$25) -> 0 | P38: =IFERROR(O38/N38,"") | Q38: =SUMIF($D$6:$D$25,$G38,Q$6:Q$25) -> 0 | R38: =SUMIF($D$6:$D$25,$G38,R$6:R$25) -> 0 | S38: =R38-Q38 -> 0 | T38: =SUMIF($D$6:$D$25,$G38,T$6:T$25) -> 0 | U38: =SUMIF($D$6:$D$25,$G38,U$6:U$25) -> 0 | V38: =IFERROR(U38/T38,"")
G39: West 2 | I39: =SUMIF($D$6:$D$25,$G39,I$6:I$25) -> 12 | J39: =SUMIF($D$6:$D$25,$G39,J$6:J$25) -> 12 | K39: =IFERROR(J39/I39,"") -> 1 | L39: =SUMIF($D$6:$D$25,$G39,L$6:L$25) -> 300 | M39: =SUMIF($D$6:$D$25,$G39,M$6:M$25) -> 25 | N39: =SUMIF($D$6:$D$25,$G39,N$6:N$25) -> 3024 | O39: =SUMIF($D$6:$D$25,$G39,O$6:O$25) -> 4236 | P39: =IFERROR(O39/N39,"") -> 1.4007937 | Q39: =SUMIF($D$6:$D$25,$G39,Q$6:Q$25) -> 8472000 | R39: =SUMIF($D$6:$D$25,$G39,R$6:R$25) -> 8072708 | S39: =R39-Q39 -> -399292 | T39: =SUMIF($D$6:$D$25,$G39,T$6:T$25) -> 6048000 | U39: =SUMIF($D$6:$D$25,$G39,U$6:U$25) -> 8072708 | V39: =IFERROR(U39/T39,"") -> 1.3347731
G40: TOTAL | I40: =SUM(I36:I39) -> 36 | J40: =SUM(J36:J39) -> 36 | K40: =IFERROR(J40/I40,"") -> 1 | M40: =SUMIF($D$6:$D$25,$G40,M$6:M$25) -> 0 | N40: =SUM(N36:N39) -> 9576 | O40: =SUM(O36:O39) -> 17498 | P40: =O40/N40 -> 1.8272765 | Q40: =SUM(Q36:Q39) -> 34996000 | R40: =SUM(R36:R39) -> 33249971 | S40: =SUM(S36:S39) -> -1746029 | T40: =SUM(T36:T39) -> 19152000 | U40: =SUM(U36:U39) -> 33249971 | V40: =IFERROR(U40/T40,"") -> 1.7361096

Sheet REGIONAL PTD
J4: Cash Reconciliation | M4: Sales Performance
C5: SIN | D5: Region | E5: Area/Location | F5: No of Work Days | G5: Hollandia Evap Milk 120g | J5: Cash Reconciliation | M5: PER REGION
G6: Target | H6: Actual | I6: %Ach. | J6: Expected | K6: Paid | L6: Variance | M6: TARGET | N6: ACTUAL | O6: %ACD
C7: ='ATD >'!C6 -> 1 | D7: ='ATD >'!D6 -> East 1 | E7: ='ATD >'!E6 -> Enugu | F7: =SUMIF('ATD >'!E:E,'REGIONAL PTD'!E7,'ATD >'!M:M) -> 0 | G7: =SUMIF('ATD >'!E:E,'REGIONAL PTD'!E7,'ATD >'!N:N) -> 0 | H7: =SUMIF('ATD >'!E:E,'REGIONAL PTD'!E7,'ATD >'!O:O) -> 0 | I7: =SUMIF('ATD >'!E:E,'REGIONAL PTD'!E7,'ATD >'!P:P) -> 0 | J7: =SUMIF('ATD >'!E:E,'REGIONAL PTD'!E7,'ATD >'!Q:Q) -> 0 | K7: =SUMIF('ATD >'!E:E,'REGIONAL PTD'!E7,'ATD >'!R:R) -> 0 | L7: =SUMIF('ATD >'!E:E,'REGIONAL PTD'!E7,'ATD >'!S:S) -> 0 | M7: =SUMIF('ATD >'!E:E,'REGIONAL PTD'!E7,'ATD >'!T:T) -> 0 | N7: =SUMIF('ATD >'!E:E,'REGIONAL PTD'!E7,'ATD >'!U:U) -> 0 | O7: =SUMIF('ATD >'!E:E,'REGIONAL PTD'!E7,'ATD >'!V:V) -> 0
C8: ='ATD >'!C7 -> 2 | D8: ='ATD >'!D7 -> East 1 | E8: ='ATD >'!E7 -> Abakaliki | F8: =SUMIF('ATD >'!E:E,'REGIONAL PTD'!E8,'ATD >'!M:M) -> 0 | G8: =SUMIF('ATD >'!E:E,'REGIONAL PTD'!E8,'ATD >'!N:N) -> 0 | H8: =SUMIF('ATD >'!E:E,'REGIONAL PTD'!E8,'ATD >'!O:O) -> 0 | I8: =SUMIF('ATD >'!E:E,'REGIONAL PTD'!E8,'ATD >'!P:P) -> 0 | J8: =SUMIF('ATD >'!E:E,'REGIONAL PTD'!E8,'ATD >'!Q:Q) -> 0 | K8: =SUMIF('ATD >'!E:E,'REGIONAL PTD'!E8,'ATD >'!R:R) -> 0 | L8: =SUMIF('ATD >'!E:E,'REGIONAL PTD'!E8,'ATD >'!S:S) -> 0 | M8: =SUMIF('ATD >'!E:E,'REGIONAL PTD'!E8,'ATD >'!T:T) -> 0 | N8: =SUMIF('ATD >'!E:E,'REGIONAL PTD'!E8,'ATD >'!U:U) -> 0 | O8: =SUMIF('ATD >'!E:E,'REGIONAL PTD'!E8,'ATD >'!V:V) -> 0
C9: ='ATD >'!C8 -> 3 | D9: ='ATD >'!D8 -> East 1 | E9: ='ATD >'!E8 -> Onitsha | F9: =SUMIF('ATD >'!E:E,'REGIONAL PTD'!E9,'ATD >'!M:M) -> 10 | G9: =SUMIF('ATD >'!E:E,'REGIONAL PTD'!E9,'ATD >'!N:N) -> 0 | H9: =SUMIF('ATD >'!E:E,'REGIONAL PTD'!E9,'ATD >'!O:O) -> 1477 | I9: =SUMIF('ATD >'!E:E,'REGIONAL PTD'!E9,'ATD >'!P:P) -> 0 | J9: =SUMIF('ATD >'!E:E,'REGIONAL PTD'!E9,'ATD >'!Q:Q) -> 2954000 | K9: =SUMIF('ATD >'!E:E,'REGIONAL PTD'!E9,'ATD >'!R:R) -> 2792792 | L9: =SUMIF('ATD >'!E:E,'REGIONAL PTD'!E9,'ATD >'!S:S) -> 161208 | M9: =SUMIF('ATD >'!E:E,'REGIONAL PTD'!E9,'ATD >'!T:T) -> 0 | N9: =SUMIF('ATD >'!E:E,'REGIONAL PTD'!E9,'ATD >'!U:U) -> 2792792 | O9: =SUMIF('ATD >'!E:E,'REGIONAL PTD'!E9,'ATD >'!V:V) -> 0
C10: ='ATD >'!C9 -> 4 | D10: ='ATD >'!D9 -> East 1 | E10: ='ATD >'!E9 -> Asaba | F10: =SUMIF('ATD >'!E:E,'REGIONAL PTD'!E10,'ATD >'!M:M) -> 9 | G10: =SUMIF('ATD >'!E:E,'REGIONAL PTD'!E10,'ATD >'!N:N) -> 0 | H10: =SUMIF('ATD >'!E:E,'REGIONAL PTD'!E10,'ATD >'!O:O) -> 674 | I10: =SUMIF('ATD >'!E:E,'REGIONAL PTD'!E10,'ATD >'!P:P) -> 0 | J10: =SUMIF('ATD >'!E:E,'REGIONAL PTD'!E10,'ATD >'!Q:Q) -> 1348000 | K10: =SUMIF('ATD >'!E:E,'REGIONAL PTD'!E10,'ATD >'!R:R) -> 1272512 | L10: =SUMIF('ATD >'!E:E,'REGIONAL PTD'!E10,'ATD >'!S:S) -> 75488 | M10: =SUMIF('ATD >'!E:E,'REGIONAL PTD'!E10,'ATD >'!T:T) -> 0 | N10: =SUMIF('ATD >'!E:E,'REGIONAL PTD'!E10,'ATD >'!U:U) -> 1272512 | O10: =SUMIF('ATD >'!E:E,'REGIONAL PTD'!E10,'ATD >'!V:V) -> 0
C11: ='ATD >'!C10 -> 5 | D11: ='ATD >'!D10 -> East 1 | E11: ='ATD >'!E10 -> Owerri | F11: =SUMIF('ATD >'!E:E,'REGIONAL PTD'!E11,'ATD >'!M:M) -> 16 | G11: =SUMIF('ATD >'!E:E,'REGIONAL PTD'!E11,'ATD >'!N:N) -> 0 | H11: =SUMIF('ATD >'!E:E,'REGIONAL PTD'!E11,'ATD >'!O:O) -> 3399 | I11: =SUMIF('ATD >'!E:E,'REGIONAL PTD'!E11,'ATD >'!P:P) -> 0 | J11: =SUMIF('ATD >'!E:E,'REGIONAL PTD'!E11,'ATD >'!Q:Q) -> 6798000 | K11: =SUMIF('ATD >'!E:E,'REGIONAL PTD'!E11,'ATD >'!R:R) -> 6476896 | L11: =SUMIF('ATD >'!E:E,'REGIONAL PTD'!E11,'ATD >'!S:S) -> 321104 | M11: =SUMIF('ATD >'!E:E,'REGIONAL PTD'!E11,'ATD >'!T:T) -> 0 | N11: =SUMIF('ATD >'!E:E,'REGIONAL PTD'!E11,'ATD >'!U:U) -> 6476896 | O11: =SUMIF('ATD >'!E:E,'REGIONAL PTD'!E11,'ATD >'!V:V) -> 0
C12: Total | G12: =SUM(G7:G11) -> 0 | H12: =SUM(H7:H11) -> 5550 | I12: =SUM(I7:I11) -> 0 | J12: =SUM(J7:J11) -> 11100000 | K12: =SUM(K7:K11) -> 10542200 | L12: =SUM(L7:L11) -> 557800 | M12: =SUM(M7:M11) -> 0 | N12: =SUM(N7:N11) -> 10542200 | O12: =N12/M12 -> #DIV/0!
J17: Cash Reconciliation | M17: Sales Performance
C18: SIN | D18: Region | E18: Area/Location | F18: No of Work Days | G18: Hollandia Evap Milk 120g | J18: Cash Reconciliation | M18: PER REGION
G19: Target | H19: Actual | I19: %Ach. | J19: Expected | K19: Paid | L19: Variance | M19: TARGET | N19: ACTUAL | O19: %ACD
C20: 1 | D20: ='ATD >'!D11 -> East 2 | E20: ='ATD >'!E11 -> Aba | F20: =SUMIF('ATD >'!E:E,'REGIONAL PTD'!E20,'ATD >'!M:M) -> 1 | G20: =SUMIF('ATD >'!E:E,E20,'ATD >'!N:N) -> 0 | H20: =SUMIF('ATD >'!E:E,'REGIONAL PTD'!E20,'ATD >'!O:O) -> 53 | I20: =SUMIF('ATD >'!E:E,'REGIONAL PTD'!E20,'ATD >'!P:P) -> 0 | J20: =SUMIF('ATD >'!E:E,'REGIONAL PTD'!E20,'ATD >'!Q:Q) -> 106000 | K20: =SUMIF('ATD >'!E:E,'REGIONAL PTD'!E20,'ATD >'!R:R) -> 100064 | L20: =SUMIF('ATD >'!E:E,'REGIONAL PTD'!E20,'ATD >'!S:S) -> 5936 | M20: =SUMIF('ATD >'!E:E,'REGIONAL PTD'!E20,'ATD >'!T:T) -> 0 | N20: =SUMIF('ATD >'!E:E,'REGIONAL PTD'!E20,'ATD >'!U:U) -> 100064 | O20: =SUMIF('ATD >'!E:E,'REGIONAL PTD'!E20,'ATD >'!V:V) -> 0
C21: 2 | D21: ='ATD >'!D12 -> East 2 | E21: ='ATD >'!E12 -> PHC 1 | F21: =SUMIF('ATD >'!E:E,'REGIONAL PTD'!E21,'ATD >'!M:M) -> 14 | G21: =SUMIF('ATD >'!E:E,E21,'ATD >'!N:N) -> 0 | H21: =SUMIF('ATD >'!E:E,'REGIONAL PTD'!E21,'ATD >'!O:O) -> 2337 | I21: =SUMIF('ATD >'!E:E,'REGIONAL PTD'!E21,'ATD >'!P:P) -> 0 | J21: =SUMIF('ATD >'!E:E,'REGIONAL PTD'!E21,'ATD >'!Q:Q) -> 4674000 | K21: =SUMIF('ATD >'!E:E,'REGIONAL PTD'!E21,'ATD >'!R:R) -> 4440480 | L21: =SUMIF('ATD >'!E:E,'REGIONAL PTD'!E21,'ATD >'!S:S) -> 233520 | M21: =SUMIF('ATD >'!E:E,'REGIONAL PTD'!E21,'ATD >'!T:T) -> 0 | N21: =SUMIF('ATD >'!E:E,'REGIONAL PTD'!E21,'ATD >'!U:U) -> 4440480 | O21: =SUMIF('ATD >'!E:E,'REGIONAL PTD'!E21,'ATD >'!V:V) -> 0
C22: 3 | D22: ='ATD >'!D13 -> East 2 | E22: ='ATD >'!E13 -> PHC 2 | F22: =SUMIF('ATD >'!E:E,'REGIONAL PTD'!E22,'ATD >'!M:M) -> 0 | G22: =SUMIF('ATD >'!E:E,E22,'ATD >'!N:N) -> 0 | H22: =SUMIF('ATD >'!E:E,'REGIONAL PTD'!E22,'ATD >'!O:O) -> 0 | I22: =SUMIF('ATD >'!E:E,'REGIONAL PTD'!E22,'ATD >'!P:P) -> 0 | J22: =SUMIF('ATD >'!E:E,'REGIONAL PTD'!E22,'ATD >'!Q:Q) -> 0 | K22: =SUMIF('ATD >'!E:E,'REGIONAL PTD'!E22,'ATD >'!R:R) -> 0 | L22: =SUMIF('ATD >'!E:E,'REGIONAL PTD'!E22,'ATD >'!S:S) -> 0 | M22: =SUMIF('ATD >'!E:E,'REGIONAL PTD'!E22,'ATD >'!T:T) -> 0 | N22: =SUMIF('ATD >'!E:E,'REGIONAL PTD'!E22,'ATD >'!U:U) -> 0 | O22: =SUMIF('ATD >'!E:E,'REGIONAL PTD'!E22,'ATD >'!V:V) -> 0
C23: 4 | D23: ='ATD >'!D14 -> East 2 | E23: ='ATD >'!E14 -> Bayelsa | F23: =SUMIF('ATD >'!E:E,'REGIONAL PTD'!E23,'ATD >'!M:M) -> 10 | G23: =SUMIF('ATD >'!E:E,E23,'ATD >'!N:N) -> 0 | H23: =SUMIF('ATD >'!E:E,'REGIONAL PTD'!E23,'ATD >'!O:O) -> 2240 | I23: =SUMIF('ATD >'!E:E,'REGIONAL PTD'!E23,'ATD >'!P:P) -> 0 | J23: =SUMIF('ATD >'!E:E,'REGIONAL PTD'!E23,'ATD >'!Q:Q) -> 4480000 | K23: =SUMIF('ATD >'!E:E,'REGIONAL PTD'!E23,'ATD >'!R:R) -> 4265211 | L23: =SUMIF('ATD >'!E:E,'REGIONAL PTD'!E23,'ATD >'!S:S) -> 214789 | M23: =SUMIF('ATD >'!E:E,'REGIONAL PTD'!E23,'ATD >'!T:T) -> 0 | N23: =SUMIF('ATD >'!E:E,'REGIONAL PTD'!E23,'ATD >'!U:U) -> 4265211 | O23: =SUMIF('ATD >'!E:E,'REGIONAL PTD'!E23,'ATD >'!V:V) -> 0
C24: 5 | D24: ='ATD >'!D15 -> East 2 | E24: ='ATD >'!E15 -> Uyo | F24: =SUMIF('ATD >'!E:E,'REGIONAL PTD'!E24,'ATD >'!M:M) -> 14 | G24: =SUMIF('ATD >'!E:E,E24,'ATD >'!N:N) -> 3528 | H24: =SUMIF('ATD >'!E:E,'REGIONAL PTD'!E24,'ATD >'!O:O) -> 1756 | I24: =SUMIF('ATD >'!E:E,'REGIONAL PTD'!E24,'ATD >'!P:P) -> 0.49773243 | J24: =SUMIF('ATD >'!E:E,'REGIONAL PTD'!E24,'ATD >'!Q:Q) -> 3512000 | K24: =SUMIF('ATD >'!E:E,'REGIONAL PTD'!E24,'ATD >'!R:R) -> 3315328 | L24: =SUMIF('ATD >'!E:E,'REGIONAL PTD'!E24,'ATD >'!S:S) -> 196672 | M24: =SUMIF('ATD >'!E:E,'REGIONAL PTD'!E24,'ATD >'!T:T) -> 7056000 | N24: =SUMIF('ATD >'!E:E,'REGIONAL PTD'!E24,'ATD >'!U:U) -> 3315328 | O24: =SUMIF('ATD >'!E:E,'REGIONAL PTD'!E24,'ATD >'!V:V) -> 0.46985941
C25: 6 | D25: ='ATD >'!D16 -> East 2 | E25: ='ATD >'!E16 -> Calabar | F25: =SUMIF('ATD >'!E:E,'REGIONAL PTD'!E25,'ATD >'!M:M) -> 12 | G25: =SUMIF('ATD >'!E:E,E25,'ATD >'!N:N) -> 3024 | H25: =SUMIF('ATD >'!E:E,'REGIONAL PTD'!E25,'ATD >'!O:O) -> 1326 | I25: =SUMIF('ATD >'!E:E,'REGIONAL PTD'!E25,'ATD >'!P:P) -> 0.43849206 | J25: =SUMIF('ATD >'!E:E,'REGIONAL PTD'!E25,'ATD >'!Q:Q) -> 2652000 | K25: =SUMIF('ATD >'!E:E,'REGIONAL PTD'!E25,'ATD >'!R:R) -> 2513980 | L25: =SUMIF('ATD >'!E:E,'REGIONAL PTD'!E25,'ATD >'!S:S) -> 138020 | M25: =SUMIF('ATD >'!E:E,'REGIONAL PTD'!E25,'ATD >'!T:T) -> 6048000 | N25: =SUMIF('ATD >'!E:E,'REGIONAL PTD'!E25,'ATD >'!U:U) -> 2513980 | O25: =SUMIF('ATD >'!E:E,'REGIONAL PTD'!E25,'ATD >'!V:V) -> 0.4156713
C26: Total | G26: =SUM(G21:G25) -> 6552 | H26: =SUM(H21:H25) -> 7659 | I26: =SUM(I21:I25) -> 0.93622449 | J26: =SUM(J21:J25) -> 15318000 | K26: =SUM(K21:K25) -> 14534999 | L26: =SUM(L21:L25) -> 783001 | M26: =SUM(M21:M25) -> 13104000 | N26: =SUM(N21:N25) -> 14534999 | O26: =N26/M26 -> 1.1092032
J32: Cash Reconciliation | M32: Sales Performance
C33: SIN | D33: Region | E33: Area/Location | F33: No of Work Days | G33: Hollandia Evap Milk 120g | J33: Cash Reconciliation | M33: PER REGION
G34: Target | H34: Actual | I34: %Ach. | J34: Expected | K34: Paid | L34: Variance | M34: TARGET | N34: ACTUAL | O34: %ACD
C35: 1 | D35: ='ATD >'!D17 -> West 1 | E35: ='ATD >'!E17 -> Ibadan 1 | F35: =SUMIF('ATD >'!E:E,'REGIONAL PTD'!E35,'ATD >'!M:M) -> 0 | G35: =SUMIF('ATD >'!E:E,E35,'ATD >'!N:N) -> 0 | H35: =SUMIF('ATD >'!E:E,'REGIONAL PTD'!E35,'ATD >'!O:O) -> 0 | I35: =SUMIF('ATD >'!E:E,'REGIONAL PTD'!E35,'ATD >'!P:P) -> 0 | J35: =SUMIF('ATD >'!E:E,'REGIONAL PTD'!E35,'ATD >'!Q:Q) -> 0 | K35: =SUMIF('ATD >'!E:E,'REGIONAL PTD'!E35,'ATD >'!R:R) -> 0 | L35: =SUMIF('ATD >'!E:E,'REGIONAL PTD'!E35,'ATD >'!S:S) -> 0 | M35: =SUMIF('ATD >'!E:E,'REGIONAL PTD'!E35,'ATD >'!T:T) -> 0 | N35: =SUMIF('ATD >'!E:E,'REGIONAL PTD'!E35,'ATD >'!U:U) -> 0 | O35: =SUMIF('ATD >'!E:E,'REGIONAL PTD'!E35,'ATD >'!V:V) -> 0
C36: 2 | D36: ='ATD >'!D18 -> West 1 | E36: ='ATD >'!E18 -> Ibadan 2 | F36: =SUMIF('ATD >'!E:E,'REGIONAL PTD'!E36,'ATD >'!M:M) -> 0 | G36: =SUMIF('ATD >'!E:E,E36,'ATD >'!N:N) -> 0 | H36: =SUMIF('ATD >'!E:E,'REGIONAL PTD'!E36,'ATD >'!O:O) -> 0 | I36: =SUMIF('ATD >'!E:E,'REGIONAL PTD'!E36,'ATD >'!P:P) -> 0 | J36: =SUMIF('ATD >'!E:E,'REGIONAL PTD'!E36,'ATD >'!Q:Q) -> 0 | K36: =SUMIF('ATD >'!E:E,'REGIONAL PTD'!E36,'ATD >'!R:R) -> 0 | L36: =SUMIF('ATD >'!E:E,'REGIONAL PTD'!E36,'ATD >'!S:S) -> 0 | M36: =SUMIF('ATD >'!E:E,'REGIONAL PTD'!E36,'ATD >'!T:T) -> 0 | N36: =SUMIF('ATD >'!E:E,'REGIONAL PTD'!E36,'ATD >'!U:U) -> 0 | O36: =SUMIF('ATD >'!E:E,'REGIONAL PTD'!E36,'ATD >'!V:V) -> 0
C37: 3 | D37: ='ATD >'!D19 -> West 1 | E37: ='ATD >'!E19 -> Oshogbo | F37: =SUMIF('ATD >'!E:E,'REGIONAL PTD'!E37,'ATD >'!M:M) -> 0 | G37: =SUMIF('ATD >'!E:E,E37,'ATD >'!N:N) -> 0 | H37: =SUMIF('ATD >'!E:E,'REGIONAL PTD'!E37,'ATD >'!O:O) -> 0 | I37: =SUMIF('ATD >'!E:E,'REGIONAL PTD'!E37,'ATD >'!P:P) -> 0 | J37: =SUMIF('ATD >'!E:E,'REGIONAL PTD'!E37,'ATD >'!Q:Q) -> 0 | K37: =SUMIF('ATD >'!E:E,'REGIONAL PTD'!E37,'ATD >'!R:R) -> 0 | L37: =SUMIF('ATD >'!E:E,'REGIONAL PTD'!E37,'ATD >'!S:S) -> 0 | M37: =SUMIF('ATD >'!E:E,'REGIONAL PTD'!E37,'ATD >'!T:T) -> 0 | N37: =SUMIF('ATD >'!E:E,'REGIONAL PTD'!E37,'ATD >'!U:U) -> 0 | O37: =SUMIF('ATD >'!E:E,'REGIONAL PTD'!E37,'ATD >'!V:V) -> 0
C38: 4 | D38: ='ATD >'!D20 -> West 1 | E38: ='ATD >'!E20 -> Ilorin | F38: =SUMIF('ATD >'!E:E,'REGIONAL PTD'!E38,'ATD >'!M:M) -> 0 | G38: =SUMIF('ATD >'!E:E,E38,'ATD >'!N:N) -> 0 | H38: =SUMIF('ATD >'!E:E,'REGIONAL PTD'!E38,'ATD >'!O:O) -> 0 | I38: =SUMIF('ATD >'!E:E,'REGIONAL PTD'!E38,'ATD >'!P:P) -> 0 | J38: =SUMIF('ATD >'!E:E,'REGIONAL PTD'!E38,'ATD >'!Q:Q) -> 0 | K38: =SUMIF('ATD >'!E:E,'REGIONAL PTD'!E38,'ATD >'!R:R) -> 0 | L38: =SUMIF('ATD >'!E:E,'REGIONAL PTD'!E38,'ATD >'!S:S) -> 0 | M38: =SUMIF('ATD >'!E:E,'REGIONAL PTD'!E38,'ATD >'!T:T) -> 0 | N38: =SUMIF('ATD >'!E:E,'REGIONAL PTD'!E38,'ATD >'!U:U) -> 0 | O38: =SUMIF('ATD >'!E:E,'REGIONAL PTD'!E38,'ATD >'!V:V) -> 0
C39: Total | G39: =SUM(G34:G38) -> 0 | H39: =SUM(H34:H38) -> 0 | I39: =SUM(I34:I38) -> 0 | J39: =SUM(J34:J38) -> 0 | K39: =SUM(K34:K38) -> 0 | L39: =SUM(L34:L38) -> 0 | M39: =SUM(M34:M38) -> 0 | N39: =SUM(N34:N38) -> 0 | O39: =N39/M39 -> #DIV/0!
J45: Cash Reconciliation | M45: Sales Performance
C46: SIN | D46: Region | E46: Area/Location | F46: No of Work Days | G46: Hollandia Evap Milk 120g | J46: Cash Reconciliation | M46: PER REGION
G47: Target | H47: Actual | I47: %Ach. | J47: Expected | K47: Paid | L47: Variance | M47: TARGET | N47: ACTUAL | O47: %ACD
C48: 1 | D48: ='ATD >'!D21 -> West 2 | E48: ='ATD >'!E21 -> Benin 1 | F48: =SUMIF('ATD >'!E:E,'REGIONAL PTD'!E48,'ATD >'!M:M) -> 0 | G48: =SUMIF('ATD >'!E:E,E48,'ATD >'!N:N) -> 0 | H48: =SUMIF('ATD >'!E:E,'REGIONAL PTD'!E48,'ATD >'!O:O) -> 0 | I48: =SUMIF('ATD >'!E:E,'REGIONAL PTD'!E48,'ATD >'!P:P) -> 0 | J48: =SUMIF('ATD >'!E:E,'REGIONAL PTD'!E48,'ATD >'!Q:Q) -> 0 | K48: =SUMIF('ATD >'!E:E,'REGIONAL PTD'!E48,'ATD >'!R:R) -> 0 | L48: =SUMIF('ATD >'!E:E,'REGIONAL PTD'!E48,'ATD >'!S:S) -> 0 | M48: =SUMIF('ATD >'!E:E,'REGIONAL PTD'!E48,'ATD >'!T:T) -> 0 | N48: =SUMIF('ATD >'!E:E,'REGIONAL PTD'!E48,'ATD >'!U:U) -> 0 | O48: =SUMIF('ATD >'!E:E,'REGIONAL PTD'!E48,'ATD >'!V:V) -> 0
C49: 2 | D49: ='ATD >'!D22 -> West 2 | E49: ='ATD >'!E22 -> Benin 2 | F49: =SUMIF('ATD >'!E:E,'REGIONAL PTD'!E49,'ATD >'!M:M) -> 0 | G49: =SUMIF('ATD >'!E:E,E49,'ATD >'!N:N) -> 0 | H49: =SUMIF('ATD >'!E:E,'REGIONAL PTD'!E49,'ATD >'!O:O) -> 0 | I49: =SUMIF('ATD >'!E:E,'REGIONAL PTD'!E49,'ATD >'!P:P) -> 0 | J49: =SUMIF('ATD >'!E:E,'REGIONAL PTD'!E49,'ATD >'!Q:Q) -> 0 | K49: =SUMIF('ATD >'!E:E,'REGIONAL PTD'!E49,'ATD >'!R:R) -> 0 | L49: =SUMIF('ATD >'!E:E,'REGIONAL PTD'!E49,'ATD >'!S:S) -> 0 | M49: =SUMIF('ATD >'!E:E,'REGIONAL PTD'!E49,'ATD >'!T:T) -> 0 | N49: =SUMIF('ATD >'!E:E,'REGIONAL PTD'!E49,'ATD >'!U:U) -> 0 | O49: =SUMIF('ATD >'!E:E,'REGIONAL PTD'!E49,'ATD >'!V:V) -> 0
C50: 3 | D50: ='ATD >'!D23 -> West 2 | E50: ='ATD >'!E23 -> Akure 1 | F50: =SUMIF('ATD >'!E:E,'REGIONAL PTD'!E50,'ATD >'!M:M) -> 0 | G50: =SUMIF('ATD >'!E:E,E50,'ATD >'!N:N) -> 0 | H50: =SUMIF('ATD >'!E:E,'REGIONAL PTD'!E50,'ATD >'!O:O) -> 0 | I50: =SUMIF('ATD >'!E:E,'REGIONAL PTD'!E50,'ATD >'!P:P) -> 0 | J50: =SUMIF('ATD >'!E:E,'REGIONAL PTD'!E50,'ATD >'!Q:Q) -> 0 | K50: =SUMIF('ATD >'!E:E,'REGIONAL PTD'!E50,'ATD >'!R:R) -> 0 | L50: =SUMIF('ATD >'!E:E,'REGIONAL PTD'!E50,'ATD >'!S:S) -> 0 | M50: =SUMIF('ATD >'!E:E,'REGIONAL PTD'!E50,'ATD >'!T:T) -> 0 | N50: =SUMIF('ATD >'!E:E,'REGIONAL PTD'!E50,'ATD >'!U:U) -> 0 | O50: =SUMIF('ATD >'!E:E,'REGIONAL PTD'!E50,'ATD >'!V:V) -> 0
C51: 4 | D51: ='ATD >'!D24 -> West 2 | E51: ='ATD >'!E24 -> Ado-Ekiti | F51: =SUMIF('ATD >'!E:E,'REGIONAL PTD'!E51,'ATD >'!M:M) -> 12 | G51: =SUMIF('ATD >'!E:E,E51,'ATD >'!N:N) -> 3024 | H51: =SUMIF('ATD >'!E:E,'REGIONAL PTD'!E51,'ATD >'!O:O) -> 1686 | I51: =SUMIF('ATD >'!E:E,'REGIONAL PTD'!E51,'ATD >'!P:P) -> 0.55753968 | J51: =SUMIF('ATD >'!E:E,'REGIONAL PTD'!E51,'ATD >'!Q:Q) -> 3372000 | K51: =SUMIF('ATD >'!E:E,'REGIONAL PTD'!E51,'ATD >'!R:R) -> 3220296 | L51: =SUMIF('ATD >'!E:E,'REGIONAL PTD'!E51,'ATD >'!S:S) -> 151704 | M51: =SUMIF('ATD >'!E:E,'REGIONAL PTD'!E51,'ATD >'!T:T) -> 6048000 | N51: =SUMIF('ATD >'!E:E,'REGIONAL PTD'!E51,'ATD >'!U:U) -> 3220296 | O51: =SUMIF('ATD >'!E:E,'REGIONAL PTD'!E51,'ATD >'!V:V) -> 0.53245635
C52: 5 | D52: ='ATD >'!D25 -> West 2 | E52: ='ATD >'!E25 -> Warri | F52: =SUMIF('ATD >'!E:E,'REGIONAL PTD'!E52,'ATD >'!M:M) -> 13 | G52: =SUMIF('ATD >'!E:E,E52,'ATD >'!N:N) -> 0 | H52: =SUMIF('ATD >'!E:E,'REGIONAL PTD'!E52,'ATD >'!O:O) -> 2550 | I52: =SUMIF('ATD >'!E:E,'REGIONAL PTD'!E52,'ATD >'!P:P) -> 0 | J52: =SUMIF('ATD >'!E:E,'REGIONAL PTD'!E52,'ATD >'!Q:Q) -> 5100000 | K52: =SUMIF('ATD >'!E:E,'REGIONAL PTD'!E52,'ATD >'!R:R) -> 4852412 | L52: =SUMIF('ATD >'!E:E,'REGIONAL PTD'!E52,'ATD >'!S:S) -> 247588 | M52: =SUMIF('ATD >'!E:E,'REGIONAL PTD'!E52,'ATD >'!T:T) -> 0 | N52: =SUMIF('ATD >'!E:E,'REGIONAL PTD'!E52,'ATD >'!U:U) -> 4852412 | O52: =SUMIF('ATD >'!E:E,'REGIONAL PTD'!E52,'ATD >'!V:V) -> 0
C53: Total | G53: =SUM(G48:G52) -> 3024 | H53: =SUM(H48:H52) -> 4236 | I53: =SUM(I48:I52) -> 0.55753968 | J53: =SUM(J48:J52) -> 8472000 | K53: =SUM(K48:K52) -> 8072708 | L53: =SUM(L48:L52) -> 399292 | M53: =SUM(M48:M52) -> 6048000 | N53: =SUM(N48:N52) -> 8072708 | O53: =N53/M53 -> 1.3347731

Sheet NEW ATD PER TEAM
C2: Start Date
C3: 45547
B5: DTC Report
G6: Promoters Update | K6: Sales Report | Z6: Cash Reconciliation | AC6: Sales Performance
B7: SIN | C7: Region | D7: Location | E7: Area | F7: Agency Supervisor | G7: Expected No of Promoters | H7: Actual Manning | I7: %Ach | J7: MAN DAYS | K7: Capri-sun 200ml x 40ml | N7: Hollandia Evap Milk 120g | Q7: Hollandia Yoghurt 90ml | T7: Hollandia Yoghurt Plain 315ml | W7: Exotic PC 315ml | Z7: Cash Reconciliation | AC7: PER REGION
C8: East 1 | K8: Target | L8: Actual | M8: %Ach. | N8: Target | O8: Actual | P8: %Ach. | Q8: Target | R8: Actual | S8: %Ach. | T8: Target | U8: Actual | V8: %Ach. | W8: Target | X8: Actual | Y8: %Ach. | Z8: Expected | AA8: Paid | AB8: Variance | AC8: TARGET | AD8: ACTUAL | AE8: %ACD
D9: Enugu | F9: JUDITH NKECHI OBIESIE
B10: 1 | D10: Team 1 | E10: Uydi-Market | G10: 8 | H10: 7 | I10: =IFERROR(H10/G10,"") -> 0.875 | J10: =SUMIF('[1]Total 2'!$I:$I,_xlfn.TEXTJOIN(" ",TRUE,'NEW ATD PER TEAM'!$D$9,'NEW ATD PER TEAM'!$D10),'[1]Total 2'!L:L) -> #VALUE! | K10: =J10*68/40 -> #VALUE! | L10: =SUMIF('[1]Total 2'!$I:$I,_xlfn.TEXTJOIN(" ",TRUE,'NEW ATD PER TEAM'!$D$9,'NEW ATD PER TEAM'!$D10),'[1]Total 2'!O:O) -> #VALUE! | M10: =IFERROR(L10/K10,0) -> 0 | N10: =J10*68/24 -> #VALUE! | O10: =SUMIF('[1]Total 2'!$I:$I,_xlfn.TEXTJOIN(" ",TRUE,'NEW ATD PER TEAM'!$D$9,'NEW ATD PER TEAM'!$D10),'[1]Total 2'!R:R) -> #VALUE! | P10: =IFERROR(O10/N10,0) -> 0 | Q10: =J10*68/24 -> #VALUE! | R10: =SUMIF('[1]Total 2'!$I:$I,_xlfn.TEXTJOIN(" ",TRUE,'NEW ATD PER TEAM'!$D$9,'NEW ATD PER TEAM'!$D10),'[1]Total 2'!U:U) -> #VALUE! | S10: =IFERROR(R10/Q10,0) -> 0 | T10: =J10*68/12 -> #VALUE! | U10: =SUMIF('[1]Total 2'!$I:$I,_xlfn.TEXTJOIN(" ",TRUE,'NEW ATD PER TEAM'!$D$9,'NEW ATD PER TEAM'!$D10),'[1]Total 2'!X:X) -> #VALUE! | V10: =IFERROR(U10/T10,0) -> 0 | W10: =J10*68/12 -> #VALUE! | X10: =SUMIF('[1]Total 2'!$I:$I,_xlfn.TEXTJOIN(" ",TRUE,'NEW ATD PER TEAM'!$D$9,'NEW ATD PER TEAM'!$D10),'[1]Total 2'!AA:AA) -> #VALUE! | Y10: =IFERROR(X10/W10,0) -> 0 | Z10: =SUMIF('[1]Total 2'!$I:$I,_xlfn.TEXTJOIN(" ",TRUE,'NEW ATD PER TEAM'!$D$9,'NEW ATD PER TEAM'!$D10),'[1]Total 2'!AC:AC) -> #VALUE! | AA10: =SUMIF('[1]Total 2'!$I:$I,_xlfn.TEXTJOIN(" ",TRUE,'NEW ATD PER TEAM'!$D$9,'NEW ATD PER TEAM'!$D10),'[1]Total 2'!AD:AD) -> #VALUE! | AB10: =SUMIF('[1]Total 2'!$I:$I,_xlfn.TEXTJOIN(" ",TRUE,'NEW ATD PER TEAM'!$D$9,'NEW ATD PER TEAM'!$D10),'[1]Total 2'!AE:AE) -> #VALUE! | AC10: =J10*1854*40 -> #VALUE! | AD10: =AA10 -> #VALUE! | AE10: =IFERROR(AD10/AC10,"")
B11: 2 | D11: Team 2 | E11: New Artisan Market | G11: 8 | H11: 4 | I11: =IFERROR(H11/G11,"") -> 0.5 | J11: =SUMIF('[1]Total 2'!$I:$I,_xlfn.TEXTJOIN(" ",TRUE,'NEW ATD PER TEAM'!$D$9,'NEW ATD PER TEAM'!$D11),'[1]Total 2'!L:L) -> #VALUE! | K11: =J11*68/40 -> #VALUE! | L11: =SUMIF('[1]Total 2'!$I:$I,_xlfn.TEXTJOIN(" ",TRUE,'NEW ATD PER TEAM'!$D$9,'NEW ATD PER TEAM'!$D11),'[1]Total 2'!O:O) -> #VALUE! | M11: =IFERROR(L11/K11,0) -> 0 | N11: =J11*68/24 -> #VALUE! | O11: =SUMIF('[1]Total 2'!$I:$I,_xlfn.TEXTJOIN(" ",TRUE,'NEW ATD PER TEAM'!$D$9,'NEW ATD PER TEAM'!$D11),'[1]Total 2'!R:R) -> #VALUE! | P11: =IFERROR(O11/N11,0) -> 0 | Q11: =J11*68/24 -> #VALUE! | R11: =SUMIF('[1]Total 2'!$I:$I,_xlfn.TEXTJOIN(" ",TRUE,'NEW ATD PER TEAM'!$D$9,'NEW ATD PER TEAM'!$D11),'[1]Total 2'!U:U) -> #VALUE! | S11: =IFERROR(R11/Q11,0) -> 0 | T11: =J11*68/12 -> #VALUE! | U11: =SUMIF('[1]Total 2'!$I:$I,_xlfn.TEXTJOIN(" ",TRUE,'NEW ATD PER TEAM'!$D$9,'NEW ATD PER TEAM'!$D11),'[1]Total 2'!X:X) -> #VALUE! | V11: =IFERROR(U11/T11,0) -> 0 | W11: =J11*68/12 -> #VALUE! | X11: =SUMIF('[1]Total 2'!$I:$I,_xlfn.TEXTJOIN(" ",TRUE,'NEW ATD PER TEAM'!$D$9,'NEW ATD PER TEAM'!$D11),'[1]Total 2'!AA:AA) -> #VALUE! | Y11: =IFERROR(X11/W11,0) -> 0 | Z11: =SUMIF('[1]Total 2'!$I:$I,_xlfn.TEXTJOIN(" ",TRUE,'NEW ATD PER TEAM'!$D$9,'NEW ATD PER TEAM'!$D11),'[1]Total 2'!AC:AC) -> #VALUE! | AA11: =SUMIF('[1]Total 2'!$I:$I,_xlfn.TEXTJOIN(" ",TRUE,'NEW ATD PER TEAM'!$D$9,'NEW ATD PER TEAM'!$D11),'[1]Total 2'!AD:AD) -> #VALUE! | AB11: =SUMIF('[1]Total 2'!$I:$I,_xlfn.TEXTJOIN(" ",TRUE,'NEW ATD PER TEAM'!$D$9,'NEW ATD PER TEAM'!$D11),'[1]Total 2'!AE:AE) -> #VALUE! | AC11: =J11*1854*40 -> #VALUE! | AD11: =AA11 -> #VALUE! | AE11: =IFERROR(AD11/AC11,"")
B12: 3 | D12: Team 3 | E12: Old Artisan Market | G12: 8 | H12: 3 | I12: =IFERROR(H12/G12,"") -> 0.375 | J12: =SUMIF('[1]Total 2'!$I:$I,_xlfn.TEXTJOIN(" ",TRUE,'NEW ATD PER TEAM'!$D$9,'NEW ATD PER TEAM'!$D12),'[1]Total 2'!L:L) -> #VALUE! | K12: =J12*68/40 -> #VALUE! | L12: =SUMIF('[1]Total 2'!$I:$I,_xlfn.TEXTJOIN(" ",TRUE,'NEW ATD PER TEAM'!$D$9,'NEW ATD PER TEAM'!$D12),'[1]Total 2'!O:O) -> #VALUE! | M12: =IFERROR(L12/K12,0) -> 0 | N12: =J12*68/24 -> #VALUE! | O12: =SUMIF('[1]Total 2'!$I:$I,_xlfn.TEXTJOIN(" ",TRUE,'NEW ATD PER TEAM'!$D$9,'NEW ATD PER TEAM'!$D12),'[1]Total 2'!R:R) -> #VALUE! | P12: =IFERROR(O12/N12,0) -> 0 | Q12: =J12*68/24 -> #VALUE! | R12: =SUMIF('[1]Total 2'!$I:$I,_xlfn.TEXTJOIN(" ",TRUE,'NEW ATD PER TEAM'!$D$9,'NEW ATD PER TEAM'!$D12),'[1]Total 2'!U:U) -> #VALUE! | S12: =IFERROR(R12/Q12,0) -> 0 | T12: =J12*68/12 -> #VALUE! | U12: =SUMIF('[1]Total 2'!$I:$I,_xlfn.TEXTJOIN(" ",TRUE,'NEW ATD PER TEAM'!$D$9,'NEW ATD PER TEAM'!$D12),'[1]Total 2'!X:X) -> #VALUE! | V12: =IFERROR(U12/T12,0) -> 0 | W12: =J12*68/12 -> #VALUE! | X12: =SUMIF('[1]Total 2'!$I:$I,_xlfn.TEXTJOIN(" ",TRUE,'NEW ATD PER TEAM'!$D$9,'NEW ATD PER TEAM'!$D12),'[1]Total 2'!AA:AA) -> #VALUE! | Y12: =IFERROR(X12/W12,0) -> 0 | Z12: =SUMIF('[1]Total 2'!$I:$I,_xlfn.TEXTJOIN(" ",TRUE,'NEW ATD PER TEAM'!$D$9,'NEW ATD PER TEAM'!$D12),'[1]Total 2'!AC:AC) -> #VALUE! | AA12: =SUMIF('[1]Total 2'!$I:$I,_xlfn.TEXTJOIN(" ",TRUE,'NEW ATD PER TEAM'!$D$9,'NEW ATD PER TEAM'!$D12),'[1]Total 2'!AD:AD) -> #VALUE! | AB12: =SUMIF('[1]Total 2'!$I:$I,_xlfn.TEXTJOIN(" ",TRUE,'NEW ATD PER TEAM'!$D$9,'NEW ATD PER TEAM'!$D12),'[1]Total 2'!AE:AE) -> #VALUE! | AC12: =J12*1854*40 -> #VALUE! | AD12: =AA12 -> #VALUE! | AE12: =IFERROR(AD12/AC12,"")
B13: 4 | D13: Team 4 | G13: 8 | I13: =IFERROR(H13/G13,"") -> 0 | J13: =SUMIF('[1]Total 2'!$I:$I,_xlfn.TEXTJOIN(" ",TRUE,'NEW ATD PER TEAM'!$D$9,'NEW ATD PER TEAM'!$D13),'[1]Total 2'!L:L) -> #VALUE! | K13: =J13*68/40 -> #VALUE! | L13: =SUMIF('[1]Total 2'!$I:$I,_xlfn.TEXTJOIN(" ",TRUE,'NEW ATD PER TEAM'!$D$9,'NEW ATD PER TEAM'!$D13),'[1]Total 2'!O:O) -> #VALUE! | M13: =IFERROR(L13/K13,0) -> 0 | N13: =J13*68/24 -> #VALUE! | O13: =SUMIF('[1]Total 2'!$I:$I,_xlfn.TEXTJOIN(" ",TRUE,'NEW ATD PER TEAM'!$D$9,'NEW ATD PER TEAM'!$D13),'[1]Total 2'!R:R) -> #VALUE! | P13: =IFERROR(O13/N13,0) -> 0 | Q13: =J13*68/24 -> #VALUE! | R13: =SUMIF('[1]Total 2'!$I:$I,_xlfn.TEXTJOIN(" ",TRUE,'NEW ATD PER TEAM'!$D$9,'NEW ATD PER TEAM'!$D13),'[1]Total 2'!U:U) -> #VALUE! | S13: =IFERROR(R13/Q13,0) -> 0 | T13: =J13*68/12 -> #VALUE! | U13: =SUMIF('[1]Total 2'!$I:$I,_xlfn.TEXTJOIN(" ",TRUE,'NEW ATD PER TEAM'!$D$9,'NEW ATD PER TEAM'!$D13),'[1]Total 2'!X:X) -> #VALUE! | V13: =IFERROR(U13/T13,0) -> 0 | W13: =J13*68/12 -> #VALUE! | X13: =SUMIF('[1]Total 2'!$I:$I,_xlfn.TEXTJOIN(" ",TRUE,'NEW ATD PER TEAM'!$D$9,'NEW ATD PER TEAM'!$D13),'[1]Total 2'!AA:AA) -> #VALUE! | Y13: =IFERROR(X13/W13,0) -> 0 | Z13: =SUMIF('[1]Total 2'!$I:$I,_xlfn.TEXTJOIN(" ",TRUE,'NEW ATD PER TEAM'!$D$9,'NEW ATD PER TEAM'!$D13),'[1]Total 2'!AC:AC) -> #VALUE! | AA13: =SUMIF('[1]Total 2'!$I:$I,_xlfn.TEXTJOIN(" ",TRUE,'NEW ATD PER TEAM'!$D$9,'NEW ATD PER TEAM'!$D13),'[1]Total 2'!AD:AD) -> #VALUE! | AB13: =SUMIF('[1]Total 2'!$I:$I,_xlfn.TEXTJOIN(" ",TRUE,'NEW ATD PER TEAM'!$D$9,'NEW ATD PER TEAM'!$D13),'[1]Total 2'!AE:AE) -> #VALUE! | AC13: =J13*1854*40 -> #VALUE! | AD13: =AA13 -> #VALUE! | AE13: =IFERROR(AD13/AC13,"")
E14: TOTAL | G14: =SUM(G10:G13) -> 32 | H14: =SUM(H10:H13) -> 14 | I14: =IFERROR(H14/G14,"") -> 0.4375 | J14: =SUM(J10:J13) -> #VALUE! | K14: =SUM(K10:K13) -> #VALUE! | L14: =SUM(L10:L13) -> #VALUE! | M14: =IFERROR(L14/K14,0) -> 0 | N14: =SUM(N10:N13) -> #VALUE! | O14: =SUM(O10:O13) -> #VALUE! | P14: =IFERROR(O14/N14,0) -> 0 | Q14: =SUM(Q10:Q13) -> #VALUE! | R14: =SUM(R10:R13) -> #VALUE! | S14: =IFERROR(R14/Q14,0) -> 0 | T14: =SUM(T10:T13) -> #VALUE! | U14: =SUM(U10:U13) -> #VALUE! | V14: =IFERROR(U14/T14,0) -> 0 | W14: =SUM(W10:W13) -> #VALUE! | X14: =SUM(X10:X13) -> #VALUE! | Y14: =IFERROR(X14/W14,0) -> 0 | Z14: =SUM(Z10:Z13) -> #VALUE! | AA14: =SUM(AA10:AA13) -> #VALUE! | AB14: =SUM(AB10:AB13) -> #VALUE! | AC14: =SUM(AC10:AC13) -> #VALUE! | AD14: =SUM(AD10:AD13) -> #VALUE! | AE14: =IFERROR(AD14/AC14,"")
D15: Abakaliki | F15: CHIMEZIE CHIKA
B16: 1 | D16: Team 1 | E16: Iboko | G16: 8 | H16: 5 | I16: =IFERROR(H16/G16,"") -> 0.625 | J16: =SUMIF('[1]Total 2'!$I:$I,_xlfn.TEXTJOIN(" ",TRUE,'NEW ATD PER TEAM'!$D$15,'NEW ATD PER TEAM'!$D16),'[1]Total 2'!L:L) -> #VALUE! | K16: =J16*68/40 -> #VALUE! | L16: =SUMIF('[1]Total 2'!$I:$I,_xlfn.TEXTJOIN(" ",TRUE,'NEW ATD PER TEAM'!$D$15,'NEW ATD PER TEAM'!$D16),'[1]Total 2'!O:O) -> #VALUE! | M16: =IFERROR(L16/K16,0) -> 0 | N16: =J16*68/24 -> #VALUE! | O16: =SUMIF('[1]Total 2'!$I:$I,_xlfn.TEXTJOIN(" ",TRUE,'NEW ATD PER TEAM'!$D$15,'NEW ATD PER TEAM'!$D16),'[1]Total 2'!R:R) -> #VALUE! | P16: =IFERROR(O16/N16,0) -> 0 | Q16: =J16*68/24 -> #VALUE! | R16: =SUMIF('[1]Total 2'!$I:$I,_xlfn.TEXTJOIN(" ",TRUE,'NEW ATD PER TEAM'!$D$15,'NEW ATD PER TEAM'!$D16),'[1]Total 2'!U:U) -> #VALUE! | S16: =IFERROR(R16/Q16,0) -> 0 | T16: =J16*68/12 -> #VALUE! | U16: =SUMIF('[1]Total 2'!$I:$I,_xlfn.TEXTJOIN(" ",TRUE,'NEW ATD PER TEAM'!$D$15,'NEW ATD PER TEAM'!$D16),'[1]Total 2'!X:X) -> #VALUE! | V16: =IFERROR(U16/T16,0) -> 0 | W16: =J16*68/12 -> #VALUE! | X16: =SUMIF('[1]Total 2'!$I:$I,_xlfn.TEXTJOIN(" ",TRUE,'NEW ATD PER TEAM'!$D$15,'NEW ATD PER TEAM'!$D16),'[1]Total 2'!AA:AA) -> #VALUE! | Y16: =IFERROR(X16/W16,0) -> 0 | Z16: =SUMIF('[1]Total 2'!$I:$I,_xlfn.TEXTJOIN(" ",TRUE,'NEW ATD PER TEAM'!$D$15,'NEW ATD PER TEAM'!$D16),'[1]Total 2'!AC:AC) -> #VALUE! | AA16: =SUMIF('[1]Total 2'!$I:$I,_xlfn.TEXTJOIN(" ",TRUE,'NEW ATD PER TEAM'!$D$15,'NEW ATD PER TEAM'!$D16),'[1]Total 2'!AD:AD) -> #VALUE! | AC16: =J16*1854*40 -> #VALUE! | AD16: =AA16 -> #VALUE! | AE16: =IFERROR(AD16/AC16,"")
B17: 2 | D17: Team 2 | E17: Ahia Ofu | G17: 8 | H17: 5 | I17: =IFERROR(H17/G17,"") -> 0.625 | J17: =SUMIF('[1]Total 2'!$I:$I,_xlfn.TEXTJOIN(" ",TRUE,'NEW ATD PER TEAM'!$D$15,'NEW ATD PER TEAM'!$D17),'[1]Total 2'!L:L) -> #VALUE! | K17: =J17*68/40 -> #VALUE! | L17: =SUMIF('[1]Total 2'!$I:$I,_xlfn.TEXTJOIN(" ",TRUE,'NEW ATD PER TEAM'!$D$15,'NEW ATD PER TEAM'!$D17),'[1]Total 2'!O:O) -> #VALUE! | M17: =IFERROR(L17/K17,0) -> 0 | N17: =J17*68/24 -> #VALUE! | O17: =SUMIF('[1]Total 2'!$I:$I,_xlfn.TEXTJOIN(" ",TRUE,'NEW ATD PER TEAM'!$D$15,'NEW ATD PER TEAM'!$D17),'[1]Total 2'!R:R) -> #VALUE! | P17: =IFERROR(O17/N17,0) -> 0 | Q17: =J17*68/24 -> #VALUE! | R17: =SUMIF('[1]Total 2'!$I:$I,_xlfn.TEXTJOIN(" ",TRUE,'NEW ATD PER TEAM'!$D$15,'NEW ATD PER TEAM'!$D17),'[1]Total 2'!U:U) -> #VALUE! | S17: =IFERROR(R17/Q17,0) -> 0 | T17: =J17*68/12 -> #VALUE! | U17: =SUMIF('[1]Total 2'!$I:$I,_xlfn.TEXTJOIN(" ",TRUE,'NEW ATD PER TEAM'!$D$15,'NEW ATD PER TEAM'!$D17),'[1]Total 2'!X:X) -> #VALUE! | V17: =IFERROR(U17/T17,0) -> 0 | W17: =J17*68/12 -> #VALUE! | X17: =SUMIF('[1]Total 2'!$I:$I,_xlfn.TEXTJOIN(" ",TRUE,'NEW ATD PER TEAM'!$D$15,'NEW ATD PER TEAM'!$D17),'[1]Total 2'!AA:AA) -> #VALUE! | Y17: =IFERROR(X17/W17,0) -> 0 | Z17: =SUMIF('[1]Total 2'!$I:$I,_xlfn.TEXTJOIN(" ",TRUE,'NEW ATD PER TEAM'!$D$15,'NEW ATD PER TEAM'!$D17),'[1]Total 2'!AC:AC) -> #VALUE! | AA17: =SUMIF('[1]Total 2'!$I:$I,_xlfn.TEXTJOIN(" ",TRUE,'NEW ATD PER TEAM'!$D$15,'NEW ATD PER TEAM'!$D17),'[1]Total 2'!AD:AD) -> #VALUE! | AC17: =J17*1854*40 -> #VALUE! | AD17: =AA17 -> #VALUE! | AE17: =IFERROR(AD17/AC17,"")
B18: 3 | D18: Team 3 | G18: 8 | I18: =IFERROR(H18/G18,"") -> 0 | J18: =SUMIF('[1]Total 2'!$I:$I,_xlfn.TEXTJOIN(" ",TRUE,'NEW ATD PER TEAM'!$D$15,'NEW ATD PER TEAM'!$D18),'[1]Total 2'!L:L) -> #VALUE! | K18: =J18*68/40 -> #VALUE! | L18: =SUMIF('[1]Total 2'!$I:$I,_xlfn.TEXTJOIN(" ",TRUE,'NEW ATD PER TEAM'!$D$15,'NEW ATD PER TEAM'!$D18),'[1]Total 2'!O:O) -> #VALUE! | M18: =IFERROR(L18/K18,0) -> 0 | N18: =J18*68/24 -> #VALUE! | O18: =SUMIF('[1]Total 2'!$I:$I,_xlfn.TEXTJOIN(" ",TRUE,'NEW ATD PER TEAM'!$D$15,'NEW ATD PER TEAM'!$D18),'[1]Total 2'!R:R) -> #VALUE! | P18: =IFERROR(O18/N18,0) -> 0 | Q18: =J18*68/24 -> #VALUE! | R18: =SUMIF('[1]Total 2'!$I:$I,_xlfn.TEXTJOIN(" ",TRUE,'NEW ATD PER TEAM'!$D$15,'NEW ATD PER TEAM'!$D18),'[1]Total 2'!U:U) -> #VALUE! | S18: =IFERROR(R18/Q18,0) -> 0 | T18: =J18*68/12 -> #VALUE! | U18: =SUMIF('[1]Total 2'!$I:$I,_xlfn.TEXTJOIN(" ",TRUE,'NEW ATD PER TEAM'!$D$15,'NEW ATD PER TEAM'!$D18),'[1]Total 2'!X:X) -> #VALUE! | V18: =IFERROR(U18/T18,0) -> 0 | W18: =J18*68/12 -> #VALUE! | X18: =SUMIF('[1]Total 2'!$I:$I,_xlfn.TEXTJOIN(" ",TRUE,'NEW ATD PER TEAM'!$D$15,'NEW ATD PER TEAM'!$D18),'[1]Total 2'!AA:AA) -> #VALUE! | Y18: =IFERROR(X18/W18,0) -> 0 | Z18: =SUMIF('[1]Total 2'!$I:$I,_xlfn.TEXTJOIN(" ",TRUE,'NEW ATD PER TEAM'!$D$15,'NEW ATD PER TEAM'!$D18),'[1]Total 2'!AC:AC) -> #VALUE! | AA18: =SUMIF('[1]Total 2'!$I:$I,_xlfn.TEXTJOIN(" ",TRUE,'NEW ATD PER TEAM'!$D$15,'NEW ATD PER TEAM'!$D18),'[1]Total 2'!AD:AD) -> #VALUE! | AC18: =J18*1854*40 -> #VALUE! | AD18: =AA18 -> #VALUE! | AE18: =IFERROR(AD18/AC18,"")
B19: 4 | D19: Team 4 | G19: 8 | I19: =IFERROR(H19/G19,"") -> 0 | J19: =SUMIF('[1]Total 2'!$I:$I,_xlfn.TEXTJOIN(" ",TRUE,'NEW ATD PER TEAM'!$D$15,'NEW ATD PER TEAM'!$D19),'[1]Total 2'!L:L) -> #VALUE! | K19: =J19*68/40 -> #VALUE! | L19: =SUMIF('[1]Total 2'!$I:$I,_xlfn.TEXTJOIN(" ",TRUE,'NEW ATD PER TEAM'!$D$15,'NEW ATD PER TEAM'!$D19),'[1]Total 2'!O:O) -> #VALUE! | M19: =IFERROR(L19/K19,0) -> 0 | N19: =J19*68/24 -> #VALUE! | O19: =SUMIF('[1]Total 2'!$I:$I,_xlfn.TEXTJOIN(" ",TRUE,'NEW ATD PER TEAM'!$D$15,'NEW ATD PER TEAM'!$D19),'[1]Total 2'!R:R) -> #VALUE! | P19: =IFERROR(O19/N19,0) -> 0 | Q19: =J19*68/24 -> #VALUE! | R19: =SUMIF('[1]Total 2'!$I:$I,_xlfn.TEXTJOIN(" ",TRUE,'NEW ATD PER TEAM'!$D$15,'NEW ATD PER TEAM'!$D19),'[1]Total 2'!U:U) -> #VALUE! | S19: =IFERROR(R19/Q19,0) -> 0 | T19: =J19*68/12 -> #VALUE! | U19: =SUMIF('[1]Total 2'!$I:$I,_xlfn.TEXTJOIN(" ",TRUE,'NEW ATD PER TEAM'!$D$15,'NEW ATD PER TEAM'!$D19),'[1]Total 2'!X:X) -> #VALUE! | V19: =IFERROR(U19/T19,0) -> 0 | W19: =J19*68/12 -> #VALUE! | X19: =SUMIF('[1]Total 2'!$I:$I,_xlfn.TEXTJOIN(" ",TRUE,'NEW ATD PER TEAM'!$D$15,'NEW ATD PER TEAM'!$D19),'[1]Total 2'!AA:AA) -> #VALUE! | Y19: =IFERROR(X19/W19,0) -> 0 | Z19: =SUMIF('[1]Total 2'!$I:$I,_xlfn.TEXTJOIN(" ",TRUE,'NEW ATD PER TEAM'!$D$15,'NEW ATD PER TEAM'!$D19),'[1]Total 2'!AC:AC) -> #VALUE! | AA19: =SUMIF('[1]Total 2'!$I:$I,_xlfn.TEXTJOIN(" ",TRUE,'NEW ATD PER TEAM'!$D$15,'NEW ATD PER TEAM'!$D19),'[1]Total 2'!AD:AD) -> #VALUE! | AC19: =J19*1854*40 -> #VALUE! | AD19: =AA19 -> #VALUE! | AE19: =IFERROR(AD19/AC19,"")
E20: TOTAL | G20: =SUM(G16:G19) -> 32 | H20: =SUM(H16:H19) -> 10 | I20: =IFERROR(H20/G20,"") -> 0.3125 | J20: =SUM(J16:J19) -> #VALUE! | K20: =SUM(K16:K19) -> #VALUE! | L20: =SUM(L16:L19) -> #VALUE! | M20: =IFERROR(L20/K20,0) -> 0 | N20: =SUM(N16:N19) -> #VALUE! | O20: =SUM(O16:O19) -> #VALUE! | P20: =IFERROR(O20/N20,0) -> 0 | Q20: =SUM(Q16:Q19) -> #VALUE! | R20: =SUM(R16:R19) -> #VALUE! | S20: =IFERROR(R20/Q20,0) -> 0 | T20: =SUM(T16:T19) -> #VALUE! | U20: =SUM(U16:U19) -> #VALUE! | V20: =IFERROR(U20/T20,0) -> 0 | W20: =SUM(W16:W19) -> #VALUE! | X20: =SUM(X16:X19) -> #VALUE! | Y20: =IFERROR(X20/W20,0) -> 0 | Z20: =SUM(Z16:Z19) -> #VALUE! | AA20: =SUM(AA16:AA19) -> #VALUE! | AB20: =SUM(AB16:AB19) -> 0 | AC20: =SUM(AC16:AC19) -> #VALUE! | AD20: =SUM(AD16:AD19) -> #VALUE! | AE20: =IFERROR(AD20/AC20,"")
D21: Onitsha | F21: SHANTEL MMESOMACHUKWU
B22: 1 | D22: Team 1 | G22: 8 | I22: =IFERROR(H22/G22,"") -> 0 | J22: =SUMIF('[1]Total 2'!$I:$I,_xlfn.TEXTJOIN(" ",TRUE,'NEW ATD PER TEAM'!$D$21,'NEW ATD PER TEAM'!$D22),'[1]Total 2'!L:L) -> #VALUE! | K22: =J22*68/40 -> #VALUE! | L22: =SUMIF('[1]Total 2'!$I:$I,_xlfn.TEXTJOIN(" ",TRUE,'NEW ATD PER TEAM'!$D$21,'NEW ATD PER TEAM'!$D22),'[1]Total 2'!O:O) -> #VALUE! | M22: =IFERROR(L22/K22,0) -> 0 | N22: =J22*68/24 -> #VALUE! | O22: =SUMIF('[1]Total 2'!$I:$I,_xlfn.TEXTJOIN(" ",TRUE,'NEW ATD PER TEAM'!$D$21,'NEW ATD PER TEAM'!$D22),'[1]Total 2'!R:R) -> #VALUE! | P22: =IFERROR(O22/N22,0) -> 0 | Q22: =J22*68/24 -> #VALUE! | R22: =SUMIF('[1]Total 2'!$I:$I,_xlfn.TEXTJOIN(" ",TRUE,'NEW ATD PER TEAM'!$D$21,'NEW ATD PER TEAM'!$D22),'[1]Total 2'!U:U) -> #VALUE! | S22: =IFERROR(R22/Q22,0) -> 0 | T22: =J22*68/12 -> #VALUE! | U22: =SUMIF('[1]Total 2'!$I:$I,_xlfn.TEXTJOIN(" ",TRUE,'NEW ATD PER TEAM'!$D$21,'NEW ATD PER TEAM'!$D22),'[1]Total 2'!X:X) -> #VALUE! | V22: =IFERROR(U22/T22,0) -> 0 | W22: =J22*68/12 -> #VALUE! | X22: =SUMIF('[1]Total 2'!$I:$I,_xlfn.TEXTJOIN(" ",TRUE,'NEW ATD PER TEAM'!$D$21,'NEW ATD PER TEAM'!$D22),'[1]Total 2'!AA:AA) -> #VALUE! | Y22: =IFERROR(X22/W22,0) -> 0 | Z22: =SUMIF('[1]Total 2'!$I:$I,_xlfn.TEXTJOIN(" ",TRUE,'NEW ATD PER TEAM'!$D$21,'NEW ATD PER TEAM'!$D22),'[1]Total 2'!AC:AC) -> #VALUE! | AA22: =SUMIF('[1]Total 2'!$I:$I,_xlfn.TEXTJOIN(" ",TRUE,'NEW ATD PER TEAM'!$D$21,'NEW ATD PER TEAM'!$D22),'[1]Total 2'!AD:AD) -> #VALUE! | AC22: =J22*1854*40 -> #VALUE! | AD22: =AA22 -> #VALUE! | AE22: =IFERROR(AD22/AC22,"")
B23: 2 | D23: Team 2 | G23: 8 | I23: =IFERROR(H23/G23,"") -> 0 | J23: =SUMIF('[1]Total 2'!$I:$I,_xlfn.TEXTJOIN(" ",TRUE,'NEW ATD PER TEAM'!$D$21,'NEW ATD PER TEAM'!$D23),'[1]Total 2'!L:L) -> #VALUE! | K23: =J23*68/40 -> #VALUE! | L23: =SUMIF('[1]Total 2'!$I:$I,_xlfn.TEXTJOIN(" ",TRUE,'NEW ATD PER TEAM'!$D$21,'NEW ATD PER TEAM'!$D23),'[1]Total 2'!O:O) -> #VALUE! | M23: =IFERROR(L23/K23,0) -> 0 | N23: =J23*68/24 -> #VALUE! | O23: =SUMIF('[1]Total 2'!$I:$I,_xlfn.TEXTJOIN(" ",TRUE,'NEW ATD PER TEAM'!$D$21,'NEW ATD PER TEAM'!$D23),'[1]Total 2'!R:R) -> #VALUE! | P23: =IFERROR(O23/N23,0) -> 0 | Q23: =J23*68/24 -> #VALUE! | R23: =SUMIF('[1]Total 2'!$I:$I,_xlfn.TEXTJOIN(" ",TRUE,'NEW ATD PER TEAM'!$D$21,'NEW ATD PER TEAM'!$D23),'[1]Total 2'!U:U) -> #VALUE! | S23: =IFERROR(R23/Q23,0) -> 0 | T23: =J23*68/12 -> #VALUE! | U23: =SUMIF('[1]Total 2'!$I:$I,_xlfn.TEXTJOIN(" ",TRUE,'NEW ATD PER TEAM'!$D$21,'NEW ATD PER TEAM'!$D23),'[1]Total 2'!X:X) -> #VALUE! | V23: =IFERROR(U23/T23,0) -> 0 | W23: =J23*68/12 -> #VALUE! | X23: =SUMIF('[1]Total 2'!$I:$I,_xlfn.TEXTJOIN(" ",TRUE,'NEW ATD PER TEAM'!$D$21,'NEW ATD PER TEAM'!$D23),'[1]Total 2'!AA:AA) -> #VALUE! | Y23: =IFERROR(X23/W23,0) -> 0 | Z23: =SUMIF('[1]Total 2'!$I:$I,_xlfn.TEXTJOIN(" ",TRUE,'NEW ATD PER TEAM'!$D$21,'NEW ATD PER TEAM'!$D23),'[1]Total 2'!AC:AC) -> #VALUE! | AA23: =SUMIF('[1]Total 2'!$I:$I,_xlfn.TEXTJOIN(" ",TRUE,'NEW ATD PER TEAM'!$D$21,'NEW ATD PER TEAM'!$D23),'[1]Total 2'!AD:AD) -> #VALUE! | AC23: =J23*1854*40 -> #VALUE! | AD23: =AA23 -> #VALUE! | AE23: =IFERROR(AD23/AC23,"")
B24: 3 | D24: Team 3 | G24: 8 | I24: =IFERROR(H24/G24,"") -> 0 | J24: =SUMIF('[1]Total 2'!$I:$I,_xlfn.TEXTJOIN(" ",TRUE,'NEW ATD PER TEAM'!$D$21,'NEW ATD PER TEAM'!$D24),'[1]Total 2'!L:L) -> #VALUE! | K24: =J24*68/40 -> #VALUE! | L24: =SUMIF('[1]Total 2'!$I:$I,_xlfn.TEXTJOIN(" ",TRUE,'NEW ATD PER TEAM'!$D$21,'NEW ATD PER TEAM'!$D24),'[1]Total 2'!O:O) -> #VALUE! | M24: =IFERROR(L24/K24,0) -> 0 | N24: =J24*68/24 -> #VALUE! | O24: =SUMIF('[1]Total 2'!$I:$I,_xlfn.TEXTJOIN(" ",TRUE,'NEW ATD PER TEAM'!$D$21,'NEW ATD PER TEAM'!$D24),'[1]Total 2'!R:R) -> #VALUE! | P24: =IFERROR(O24/N24,0) -> 0 | Q24: =J24*68/24 -> #VALUE! | R24: =SUMIF('[1]Total 2'!$I:$I,_xlfn.TEXTJOIN(" ",TRUE,'NEW ATD PER TEAM'!$D$21,'NEW ATD PER TEAM'!$D24),'[1]Total 2'!U:U) -> #VALUE! | S24: =IFERROR(R24/Q24,0) -> 0 | T24: =J24*68/12 -> #VALUE! | U24: =SUMIF('[1]Total 2'!$I:$I,_xlfn.TEXTJOIN(" ",TRUE,'NEW ATD PER TEAM'!$D$21,'NEW ATD PER TEAM'!$D24),'[1]Total 2'!X:X) -> #VALUE! | V24: =IFERROR(U24/T24,0) -> 0 | W24: =J24*68/12 -> #VALUE! | X24: =SUMIF('[1]Total 2'!$I:$I,_xlfn.TEXTJOIN(" ",TRUE,'NEW ATD PER TEAM'!$D$21,'NEW ATD PER TEAM'!$D24),'[1]Total 2'!AA:AA) -> #VALUE! | Y24: =IFERROR(X24/W24,0) -> 0 | Z24: =SUMIF('[1]Total 2'!$I:$I,_xlfn.TEXTJOIN(" ",TRUE,'NEW ATD PER TEAM'!$D$21,'NEW ATD PER TEAM'!$D24),'[1]Total 2'!AC:AC) -> #VALUE! | AA24: =SUMIF('[1]Total 2'!$I:$I,_xlfn.TEXTJOIN(" ",TRUE,'NEW ATD PER TEAM'!$D$21,'NEW ATD PER TEAM'!$D24),'[1]Total 2'!AD:AD) -> #VALUE! | AC24: =J24*1854*40 -> #VALUE! | AD24: =AA24 -> #VALUE! | AE24: =IFERROR(AD24/AC24,"")
